Workbook

Sheet Sheet1
B2: Today's deliverable | C2: 45762
B4: NEW KPI-Done & Aligned, shared with NML as per below email. | C4: Done
B5: Supplement KPI - Done & Aligned, shared with NML as per below email. | C5: Done
B7: VA – To be sent today, COB. WIP
B8: Actual
B9: Vs 2+1 corrected version | C9: Done
B10: VS PY YTD (ROP)
B11: VS 0+3 QTD (New KPI) | C11: Done
B13: BP
B14: BP25 Q1 vs FY24 Q4
B15: BP25 FY vs FY24 FY

Sheet Summary month
E2: Apr | F2: Select Month
B4: CMP-I + Fixed Cost
B5: M EUR | F5: Actual | K5: BP | O5: Act vs BP | T5: FC 2+10 | X5: Act vs FC2+10 | AC5: OL (1+2) | AG5: Act vs OL | AL5: LY | AP5: Act vs LY | AU5: Previous month | AV5: MoM M09 vs M08 | AX5: FC 5+7 | BB5: Act vs FC 5+7 | BG5: OL (1+2) | BK5: Act vs OL (0+3) | BP5: OL (2+1) | BT5: OL(2+1)vs OL (0+3) | BY5: Jun MTD vs OL(2+1) | CA5: Q2 FC 2+10 | CC5: Q2(2+10) vs Jun FY25 Q1 | CE5: FC 7+5 | CI5: Act vs FC 7+5 | CM5: 7+5 Q4 | CN5: Q3 Actual vs 7+5 Q4
F6: =Act!S5 -> M01 | G6: =Act!T5 -> M02 | H6: =Act!U5 -> M03 | I6: Q4 | K6: =F6 -> M01 | L6: =G6 -> M02 | M6: =H6 -> M03 | N6: =I6 -> Q4 | O6: =K6 -> M01 | P6: =L6 -> M02 | Q6: =M6 -> M03 | R6: =N6 -> Q4 | T6: =F6 -> M01 | U6: =G6 -> M02 | V6: =H6 -> M03 | W6: =I6 -> Q4 | X6: =F6 -> M01 | Y6: =G6 -> M02 | Z6: =H6 -> M03 | AA6: =W6 -> Q4 | AC6: =O6 -> M01 | AD6: =P6 -> M02 | AE6: =Q6 -> M03 | AF6: =R6 -> Q4 | AG6: =O6 -> M01 | AH6: =P6 -> M02 | AI6: =Q6 -> M03 | AJ6: =AF6 -> Q4 | AL6: =X6 -> M01 | AM6: =Y6 -> M02 | AN6: =Z6 -> M03 | AO6: =AA6 -> Q4 | AP6: =X6 -> M01 | AQ6: =Y6 -> M02 | AR6: =Z6 -> M03 | AS6: =AO6 -> Q4 | AU6: M08 | AV6: M09 | AX6: =AL6 -> M01 | AY6: =AM6 -> M02 | AZ6: =AN6 -> M03 | BA6: =AO6 -> Q4 | BB6: =AP6 -> M01 | BC6: =AQ6 -> M02 | BD6: =AR6 -> M03 | BE6: =AS6 -> Q4 | BG6: =F6 -> M01 | BH6: =G6 -> M02 | BI6: =H6 -> M03 | BJ6: =I6 -> Q4 | BK6: =BG6 -> M01 | BL6: =BH6 -> M02 | BM6: =BI6 -> M03 | BN6: =BJ6 -> Q4 | BP6: =O6 -> M01 | BQ6: =P6 -> M02 | BR6: =Q6 -> M03 | BS6: =R6 -> Q4 | BT6: =BP6 -> M01 | BU6: =BQ6 -> M02 | BV6: =BR6 -> M03 | BW6: =BS6 -> Q4 | BY6: =BV6 -> M03 | CA6: Q2 | CC6: Q1 | CE6: =AX6 -> M01 | CF6: =AY6 -> M02 | CG6: =AZ6 -> M03 | CH6: =I6 -> Q4 | CI6: =CE6 -> M01 | CJ6: =CF6 -> M02 | CK6: =CG6 -> M03 | CL6: =CH6 -> Q4
C7: TIV | F7: =IF(Act!S$3=1,Act!S6,"") -> 1356.722 | G7: =IF(Act!T$3=1,Act!T6,"") | H7: =IF(Act!U$3=1,Act!U6,"") | I7: =SUM(F7:H7) -> 1356.722 | K7: =IF(BP!S$3=1,BP!S6,"") -> 1306.0789 | L7: =IF(BP!T$3=1,BP!T6,"") | M7: =IF(BP!U$3=1,BP!U6,"") | N7: =SUM(K7:M7) -> 1306.0789 | O7: =IFERROR(F7-K7,0) -> 50.643078 | P7: =IFERROR(G7-L7,0) -> 0 | Q7: =IFERROR(H7-M7,0) -> 0 | R7: =I7-N7 -> 50.643078 | T7: =IF('FC2+10'!S$3=1,'FC2+10'!S6,"") -> 1356.721 | U7: =IF('FC2+10'!T$3=1,'FC2+10'!T6,"") | V7: =IF('FC2+10'!U$3=1,'FC2+10'!U6,"") | W7: =SUM(T7:V7) -> 1356.721 | X7: =IFERROR(F7-T7,0) -> 0.001 | Y7: =IFERROR(G7-U7,0) -> 0 | Z7: =IFERROR(H7-V7,0) -> 0 | AA7: =I7-W7 -> 0.001 | AC7: =IF(OL!S$3=1,OL!S6,"") -> 1238.3779 | AD7: =IF(OL!T$3=1,OL!T6,"") -> 1315.161 | AE7: =IF(OL!U$3=1,OL!U6,"") | AF7: =SUM(AC7:AE7) -> 2553.5389 | AG7: =IFERROR(F7-AC7,0) -> 118.3441 | AH7: =IFERROR(G7-AD7,0) -> 0 | AI7: =IFERROR(H7-AE7,0) -> 0 | AJ7: =IFERROR(I7-AF7,0) -> -1196.8169 | AL7: =IF(LY!S$3=1,LY!S6,"") -> 1354.65 | AM7: =IF(LY!T$3=1,LY!T6,"") | AN7: =IF(LY!U$3=1,LY!U6,"") | AO7: =SUM(AL7:AN7) -> 1354.65 | AP7: =IFERROR(F7-AL7,0) -> 2.072 | AQ7: =IFERROR(G7-AM7,0) -> 0 | AR7: =IFERROR(H7-AN7,0) -> 0 | AS7: =IFERROR(I7-AO7,0) -> 2.072 | AU7: =Act!L6 -> 1406.473 | AV7: =H7-AU7 -> #VALUE! | AX7: =IF('FC5+7'!S$3=1,'FC5+7'!S6,"") -> 1356.721 | AY7: =IF('FC5+7'!T$3=1,'FC5+7'!T6,"") | AZ7: =IF('FC5+7'!U$3=1,'FC5+7'!U6,"") | BA7: =SUM(AX7:AZ7) -> 1356.721 | BB7: =IFERROR(F7-AX7,0) -> 0.001 | BC7: =IFERROR(G7-AY7,0) -> 0 | BD7: =IFERROR(H7-AZ7,0) -> 0 | BE7: =IFERROR(I7-BA7,0) -> 0.001 | BG7: =F7 -> 1356.722 | BH7: 1374.0032 | BI7: 1555.0535 | BJ7: =SUM(BG7:BI7) -> 4285.7787 | BK7: =IFERROR(F7-AC7,0) -> 118.3441 | BL7: =IFERROR(G7-AD7,0) -> 0 | BM7: =IFERROR(AL7-AE7,0) -> 0 | BN7: =IFERROR(I7-BJ7,0) -> -2929.0567 | BP7: =F7 -> 1356.722 | BQ7: =G7 | BR7: =#REF! -> #REF! | BS7: =SUM(BP7:BR7) -> #REF! | BT7: =BP7-AC7 -> 118.3441 | BU7: =BQ7-AD7 -> #VALUE! | BV7: =BR7-AE7 -> #REF! | BW7: =BS7-AF7 -> #REF! | BY7: =H7-BR7 -> #VALUE! | CA7: ='FC2+10'!AA6 -> 3738.528 | CC7: =CA7-I7 -> 2381.806 | CE7: =IF('FC7+5'!S$3=1,'FC7+5'!S6,"") -> 1356.721 | CF7: =IF('FC7+5'!T$3=1,'FC7+5'!T6,"") | CG7: =IF('FC7+5'!U$3=1,'FC7+5'!U6,"") | CH7: =SUM(CE7:CG7) -> 1356.721 | CI7: =IFERROR(F7-CE7,0) -> 0.001 | CJ7: =IFERROR(G7-CF7,0) -> 0 | CK7: =IFERROR(H7-CG7,0) -> 0 | CL7: =IFERROR(I7-CH7,0) -> 0.001 | CM7: =IF('FC7+5'!AC$3=1,'FC7+5'!AC6,"") -> 4279.805 | CN7: =I7-CM7 -> -2923.083
C8: Retail sales volume (K units) - NISSAN | F8: =IF(Act!S$3=1,Act!S7,"") -> 20.429 | G8: =IF(Act!T$3=1,Act!T7,"") | H8: =IF(Act!U$3=1,Act!U7,"") | I8: =SUM(F8:H8) -> 20.429 | K8: =IF(BP!S$3=1,BP!S7,"") -> 21.907 | L8: =IF(BP!T$3=1,BP!T7,"") | M8: =IF(BP!U$3=1,BP!U7,"") | N8: =SUM(K8:M8) -> 21.907 | O8: =IFERROR(F8-K8,0) -> -1.478 | P8: =IFERROR(G8-L8,0) -> 0 | Q8: =IFERROR(H8-M8,0) -> 0 | R8: =F8-K8 -> -1.478 | T8: =IF('FC2+10'!S$3=1,'FC2+10'!S7,"") -> 20.429 | U8: =IF('FC2+10'!T$3=1,'FC2+10'!T7,"") | V8: =IF('FC2+10'!U$3=1,'FC2+10'!U7,"") | W8: =SUM(T8:V8) -> 20.429 | X8: =IFERROR(F8-T8,0) -> 0 | Y8: =IFERROR(G8-U8,0) -> 0 | Z8: =IFERROR(H8-V8,0) -> 0 | AA8: =I8-W8 -> 0 | AC8: =IF(OL!S$3=1,OL!S7,"") -> 28.803 | AD8: =IF(OL!T$3=1,OL!T7,"") -> 23.689 | AE8: =IF(OL!U$3=1,OL!U7,"") | AF8: =SUM(AC8:AE8) -> 52.492 | AG8: =IFERROR(F8-AC8,0) -> -8.374 | AH8: =IFERROR(G8-AD8,0) -> 0 | AI8: =IFERROR(H8-AE8,0) -> 0 | AJ8: =IFERROR(I8-AF8,0) -> -32.063 | AL8: =IF(LY!S$3=1,LY!S7,"") -> 22.135 | AM8: =IF(LY!T$3=1,LY!T7,"") | AN8: =IF(LY!U$3=1,LY!U7,"") | AO8: =SUM(AL8:AN8) -> 22.135 | AP8: =IFERROR(F8-AL8,0) -> -1.706 | AQ8: =IFERROR(G8-AM8,0) -> 0 | AR8: =IFERROR(H8-AN8,0) -> 0 | AS8: =IFERROR(I8-AO8,0) -> -1.706 | AU8: =Act!L7 -> 28.564 | AV8: =H8-AU8 -> #VALUE! | AX8: =IF('FC5+7'!S$3=1,'FC5+7'!S7,"") -> 20.429 | AY8: =IF('FC5+7'!T$3=1,'FC5+7'!T7,"") | AZ8: =IF('FC5+7'!U$3=1,'FC5+7'!U7,"") | BA8: =SUM(AX8:AZ8) -> 20.429 | BB8: =IFERROR(F8-AX8,0) -> 0 | BC8: =IFERROR(G8-AY8,0) -> 0 | BD8: =IFERROR(H8-AZ8,0) -> 0 | BE8: =IFERROR(I8-BA8,0) -> 0 | BG8: =F8 -> 20.429 | BH8: 27.635 | BI8: 34.498 | BJ8: =SUM(BG8:BI8) -> 82.562 | BK8: =IFERROR(F8-AC8,0) -> -8.374 | BL8: =IFERROR(G8-AD8,0) -> 0 | BM8: =IFERROR(AL8-AE8,0) -> 0 | BN8: =IFERROR(I8-BJ8,0) -> -62.133 | BP8: =F8 -> 20.429 | BQ8: =G8 | BR8: =#REF! -> #REF! | BS8: =SUM(BP8:BR8) -> #REF! | BT8: =BP8-AC8 -> -8.374 | BU8: =BQ8-AD8 -> #VALUE! | BV8: =BR8-AE8 -> #REF! | BW8: =BS8-AF8 -> #REF! | BY8: =H8-BR8 -> #VALUE! | CA8: ='FC2+10'!AA7 -> 80.376 | CC8: =CA8-I8 -> 59.947 | CE8: =IF('FC7+5'!S$3=1,'FC7+5'!S7,"") -> 20.429 | CF8: =IF('FC7+5'!T$3=1,'FC7+5'!T7,"") | CG8: =IF('FC7+5'!U$3=1,'FC7+5'!U7,"") | CH8: =SUM(CE8:CG8) -> 20.429 | CI8: =IFERROR(F8-CE8,0) -> 0 | CJ8: =IFERROR(G8-CF8,0) -> 0 | CK8: =IFERROR(H8-CG8,0) -> 0 | CL8: =IFERROR(I8-CH8,0) -> 0 | CM8: =IF('FC7+5'!AC$3=1,'FC7+5'!AC7,"") -> 105.196 | CN8: =I8-CM8 -> -84.767
C9: Retail sales volume (K units) - INFINITI | F9: =IF(Act!S$3=1,Act!S8,"") -> 0 | G9: =IF(Act!T$3=1,Act!T8,"") | H9: =IF(Act!U$3=1,Act!U8,"") | I9: =SUM(F9:H9) -> 0 | K9: =IF(BP!S$3=1,BP!S8,"") -> 0 | L9: =IF(BP!T$3=1,BP!T8,"") | M9: =IF(BP!U$3=1,BP!U8,"") | N9: =SUM(K9:M9) -> 0 | O9: =IFERROR(F9-K9,0) -> 0 | P9: =IFERROR(G9-L9,0) -> 0 | Q9: =IFERROR(H9-M9,0) -> 0 | R9: =F9-K9 -> 0 | T9: =IF('FC2+10'!S$3=1,'FC2+10'!S8,"") -> 0 | U9: =IF('FC2+10'!T$3=1,'FC2+10'!T8,"") | V9: =IF('FC2+10'!U$3=1,'FC2+10'!U8,"") | W9: =SUM(T9:V9) -> 0 | X9: =IFERROR(F9-T9,0) -> 0 | Y9: =IFERROR(G9-U9,0) -> 0 | Z9: =IFERROR(H9-V9,0) -> 0 | AA9: =I9-W9 -> 0 | AC9: =IF(OL!S$3=1,OL!S8,"") -> 0 | AD9: =IF(OL!T$3=1,OL!T8,"") -> 0 | AE9: =IF(OL!U$3=1,OL!U8,"") | AF9: =SUM(AC9:AE9) -> 0 | AG9: =IFERROR(F9-AC9,0) -> 0 | AH9: =IFERROR(G9-AD9,0) -> 0 | AI9: =IFERROR(H9-AE9,0) -> 0 | AJ9: =IFERROR(I9-AF9,0) -> 0 | AL9: =IF(LY!S$3=1,LY!S8,"") -> 0 | AM9: =IF(LY!T$3=1,LY!T8,"") | AN9: =IF(LY!U$3=1,LY!U8,"") | AO9: =SUM(AL9:AN9) -> 0 | AP9: =IFERROR(F9-AL9,0) -> 0 | AQ9: =IFERROR(G9-AM9,0) -> 0 | AR9: =IFERROR(H9-AN9,0) -> 0 | AS9: =IFERROR(I9-AO9,0) -> 0 | AU9: =Act!L8 -> 0 | AV9: =H9-AU9 -> #VALUE! | AX9: =IF('FC5+7'!S$3=1,'FC5+7'!S8,"") -> 0 | AY9: =IF('FC5+7'!T$3=1,'FC5+7'!T8,"") | AZ9: =IF('FC5+7'!U$3=1,'FC5+7'!U8,"") | BA9: =SUM(AX9:AZ9) -> 0 | BB9: =IFERROR(F9-AX9,0) -> 0 | BC9: =IFERROR(G9-AY9,0) -> 0 | BD9: =IFERROR(H9-AZ9,0) -> 0 | BE9: =IFERROR(I9-BA9,0) -> 0 | BG9: =F9 -> 0 | BH9: 0 | BI9: 0 | BJ9: =SUM(BG9:BI9) -> 0 | BK9: =IFERROR(F9-AC9,0) -> 0 | BL9: =IFERROR(G9-AD9,0) -> 0 | BM9: =IFERROR(AL9-AE9,0) -> 0 | BN9: =IFERROR(I9-BJ9,0) -> 0 | BP9: =F9 -> 0 | BQ9: =G9 | BR9: =#REF! -> #REF! | BS9: =SUM(BP9:BR9) -> #REF! | BT9: =BP9-AC9 -> 0 | BU9: =BQ9-AD9 -> #VALUE! | BV9: =BR9-AE9 -> #REF! | BW9: =BS9-AF9 -> #REF! | BY9: =H9-BR9 -> #VALUE! | CA9: ='FC2+10'!AA8 -> 0 | CC9: =CA9-I9 -> 0 | CE9: =IF('FC7+5'!S$3=1,'FC7+5'!S8,"") -> 0 | CF9: =IF('FC7+5'!T$3=1,'FC7+5'!T8,"") | CG9: =IF('FC7+5'!U$3=1,'FC7+5'!U8,"") | CH9: =SUM(CE9:CG9) -> 0 | CI9: =IFERROR(F9-CE9,0) -> 0 | CJ9: =IFERROR(G9-CF9,0) -> 0 | CK9: =IFERROR(H9-CG9,0) -> 0 | CL9: =IFERROR(I9-CH9,0) -> 0 | CM9: =IF('FC7+5'!AC$3=1,'FC7+5'!AC8,"") -> 0 | CN9: =I9-CM9 -> 0
C10: Retail sales volume (K units) - DATSUN | F10: =IF(Act!S$3=1,Act!S9,"") -> 0 | G10: =IF(Act!T$3=1,Act!T9,"") | H10: =IF(Act!U$3=1,Act!U9,"") | I10: =SUM(F10:H10) -> 0 | K10: =IF(BP!S$3=1,BP!S9,"") -> 0 | L10: =IF(BP!T$3=1,BP!T9,"") | M10: =IF(BP!U$3=1,BP!U9,"") | N10: =SUM(K10:M10) -> 0 | O10: =IFERROR(F10-K10,0) -> 0 | P10: =IFERROR(G10-L10,0) -> 0 | Q10: =IFERROR(H10-M10,0) -> 0 | R10: =F10-K10 -> 0 | T10: =IF('FC2+10'!S$3=1,'FC2+10'!S9,"") -> 0 | U10: =IF('FC2+10'!T$3=1,'FC2+10'!T9,"") | V10: =IF('FC2+10'!U$3=1,'FC2+10'!U9,"") | W10: =SUM(T10:V10) -> 0 | X10: =IFERROR(F10-T10,0) -> 0 | Y10: =IFERROR(G10-U10,0) -> 0 | Z10: =IFERROR(H10-V10,0) -> 0 | AA10: =I10-W10 -> 0 | AC10: =IF(OL!S$3=1,OL!S9,"") -> 0 | AD10: =IF(OL!T$3=1,OL!T9,"") -> 0 | AE10: =IF(OL!U$3=1,OL!U9,"") | AF10: =SUM(AC10:AE10) -> 0 | AG10: =IFERROR(F10-AC10,0) -> 0 | AH10: =IFERROR(G10-AD10,0) -> 0 | AI10: =IFERROR(H10-AE10,0) -> 0 | AJ10: =IFERROR(I10-AF10,0) -> 0 | AL10: =IF(LY!S$3=1,LY!S9,"") -> 0 | AM10: =IF(LY!T$3=1,LY!T9,"") | AN10: =IF(LY!U$3=1,LY!U9,"") | AO10: =SUM(AL10:AN10) -> 0 | AP10: =IFERROR(F10-AL10,0) -> 0 | AQ10: =IFERROR(G10-AM10,0) -> 0 | AR10: =IFERROR(H10-AN10,0) -> 0 | AS10: =IFERROR(I10-AO10,0) -> 0 | AU10: =Act!L9 -> 0 | AV10: =H10-AU10 -> #VALUE! | AX10: =IF('FC5+7'!S$3=1,'FC5+7'!S9,"") -> 0 | AY10: =IF('FC5+7'!T$3=1,'FC5+7'!T9,"") | AZ10: =IF('FC5+7'!U$3=1,'FC5+7'!U9,"") | BA10: =SUM(AX10:AZ10) -> 0 | BB10: =IFERROR(F10-AX10,0) -> 0 | BC10: =IFERROR(G10-AY10,0) -> 0 | BD10: =IFERROR(H10-AZ10,0) -> 0 | BE10: =IFERROR(I10-BA10,0) -> 0 | BG10: =F10 -> 0 | BH10: 0 | BI10: 0 | BJ10: =SUM(BG10:BI10) -> 0 | BK10: =IFERROR(F10-AC10,0) -> 0 | BL10: =IFERROR(G10-AD10,0) -> 0 | BM10: =IFERROR(AL10-AE10,0) -> 0 | BN10: =IFERROR(I10-BJ10,0) -> 0 | BP10: =F10 -> 0 | BQ10: =G10 | BR10: =#REF! -> #REF! | BS10: =SUM(BP10:BR10) -> #REF! | BT10: =BP10-AC10 -> 0 | BU10: =BQ10-AD10 -> #VALUE! | BV10: =BR10-AE10 -> #REF! | BW10: =BS10-AF10 -> #REF! | BY10: =H10-BR10 -> #VALUE! | CA10: ='FC2+10'!AA9 -> 0 | CC10: =CA10-I10 -> 0 | CE10: =IF('FC7+5'!S$3=1,'FC7+5'!S9,"") -> 0 | CF10: =IF('FC7+5'!T$3=1,'FC7+5'!T9,"") | CG10: =IF('FC7+5'!U$3=1,'FC7+5'!U9,"") | CH10: =SUM(CE10:CG10) -> 0 | CI10: =IFERROR(F10-CE10,0) -> 0 | CJ10: =IFERROR(G10-CF10,0) -> 0 | CK10: =IFERROR(H10-CG10,0) -> 0 | CL10: =IFERROR(I10-CH10,0) -> 0 | CM10: =IF('FC7+5'!AC$3=1,'FC7+5'!AC9,"") -> 0 | CN10: =I10-CM10 -> 0
C11: Wholesale volume (K units) To third party (Domestic) - NISSAN | F11: =IF(Act!S$3=1,Act!S10,"") -> 16.118 | G11: =IF(Act!T$3=1,Act!T10,"") | H11: =IF(Act!U$3=1,Act!U10,"") | I11: =SUM(F11:H11) -> 16.118 | K11: =IF(BP!S$3=1,BP!S10,"") -> 15.357 | L11: =IF(BP!T$3=1,BP!T10,"") | M11: =IF(BP!U$3=1,BP!U10,"") | N11: =SUM(K11:M11) -> 15.357 | O11: =IFERROR(F11-K11,0) -> 0.761 | P11: =IFERROR(G11-L11,0) -> 0 | Q11: =IFERROR(H11-M11,0) -> 0 | R11: =F11-K11 -> 0.761 | T11: =IF('FC2+10'!S$3=1,'FC2+10'!S10,"") -> 16.118 | U11: =IF('FC2+10'!T$3=1,'FC2+10'!T10,"") | V11: =IF('FC2+10'!U$3=1,'FC2+10'!U10,"") | W11: =SUM(T11:V11) -> 16.118 | X11: =IFERROR(F11-T11,0) -> 0 | Y11: =IFERROR(G11-U11,0) -> 0 | Z11: =IFERROR(H11-V11,0) -> 0 | AA11: =I11-W11 -> 0 | AC11: =IF(OL!S$3=1,OL!S10,"") -> 28.884 | AD11: =IF(OL!T$3=1,OL!T10,"") -> 32.724 | AE11: =IF(OL!U$3=1,OL!U10,"") | AF11: =SUM(AC11:AE11) -> 61.608 | AG11: =IFERROR(F11-AC11,0) -> -12.766 | AH11: =IFERROR(G11-AD11,0) -> 0 | AI11: =IFERROR(H11-AE11,0) -> 0 | AJ11: =IFERROR(I11-AF11,0) -> -45.49 | AL11: =IF(LY!S$3=1,LY!S10,"") -> 21.245 | AM11: =IF(LY!T$3=1,LY!T10,"") | AN11: =IF(LY!U$3=1,LY!U10,"") | AO11: =SUM(AL11:AN11) -> 21.245 | AP11: =IFERROR(F11-AL11,0) -> -5.127 | AQ11: =IFERROR(G11-AM11,0) -> 0 | AR11: =IFERROR(H11-AN11,0) -> 0 | AS11: =IFERROR(I11-AO11,0) -> -5.127 | AU11: =Act!L10 -> 31.667 | AV11: =H11-AU11 -> #VALUE! | AX11: =IF('FC5+7'!S$3=1,'FC5+7'!S10,"") -> 16.118 | AY11: =IF('FC5+7'!T$3=1,'FC5+7'!T10,"") | AZ11: =IF('FC5+7'!U$3=1,'FC5+7'!U10,"") | BA11: =SUM(AX11:AZ11) -> 16.118 | BB11: =IFERROR(F11-AX11,0) -> 0 | BC11: =IFERROR(G11-AY11,0) -> 0 | BD11: =IFERROR(H11-AZ11,0) -> 0 | BE11: =IFERROR(I11-BA11,0) -> 0 | BG11: =F11 -> 16.118 | BH11: 20.752 | BI11: 33.695 | BJ11: =SUM(BG11:BI11) -> 70.565 | BK11: =IFERROR(F11-AC11,0) -> -12.766 | BL11: =IFERROR(G11-AD11,0) -> 0 | BM11: =IFERROR(AL11-AE11,0) -> 0 | BN11: =IFERROR(I11-BJ11,0) -> -54.447 | BP11: =F11 -> 16.118 | BQ11: =G11 | BR11: =#REF! -> #REF! | BS11: =SUM(BP11:BR11) -> #REF! | BT11: =BP11-AC11 -> -12.766 | BU11: =BQ11-AD11 -> #VALUE! | BV11: =BR11-AE11 -> #REF! | BW11: =BS11-AF11 -> #REF! | BY11: =H11-BR11 -> #VALUE! | CA11: ='FC2+10'!AA10 -> 76.488 | CC11: =CA11-I11 -> 60.37 | CE11: =IF('FC7+5'!S$3=1,'FC7+5'!S10,"") -> 16.118 | CF11: =IF('FC7+5'!T$3=1,'FC7+5'!T10,"") | CG11: =IF('FC7+5'!U$3=1,'FC7+5'!U10,"") | CH11: =SUM(CE11:CG11) -> 16.118 | CI11: =IFERROR(F11-CE11,0) -> 0 | CJ11: =IFERROR(G11-CF11,0) -> 0 | CK11: =IFERROR(H11-CG11,0) -> 0 | CL11: =IFERROR(I11-CH11,0) -> 0 | CM11: =IF('FC7+5'!AC$3=1,'FC7+5'!AC10,"") -> 107.634 | CN11: =I11-CM11 -> -91.516
C12: Wholesale volume (K units) To third party (Domestic) - INFINITI | F12: =IF(Act!S$3=1,Act!S11,"") -> 0.007 | G12: =IF(Act!T$3=1,Act!T11,"") | H12: =IF(Act!U$3=1,Act!U11,"") | I12: =SUM(F12:H12) -> 0.007 | K12: =IF(BP!S$3=1,BP!S11,"") -> 0.009 | L12: =IF(BP!T$3=1,BP!T11,"") | M12: =IF(BP!U$3=1,BP!U11,"") | N12: =SUM(K12:M12) -> 0.009 | O12: =IFERROR(F12-K12,0) -> -0.002 | P12: =IFERROR(G12-L12,0) -> 0 | Q12: =IFERROR(H12-M12,0) -> 0 | R12: =F12-K12 -> -0.002 | T12: =IF('FC2+10'!S$3=1,'FC2+10'!S11,"") -> 0.007 | U12: =IF('FC2+10'!T$3=1,'FC2+10'!T11,"") | V12: =IF('FC2+10'!U$3=1,'FC2+10'!U11,"") | W12: =SUM(T12:V12) -> 0.007 | X12: =IFERROR(F12-T12,0) -> 0 | Y12: =IFERROR(G12-U12,0) -> 0 | Z12: =IFERROR(H12-V12,0) -> 0 | AA12: =I12-W12 -> 0 | AC12: =IF(OL!S$3=1,OL!S11,"") -> 0.002 | AD12: =IF(OL!T$3=1,OL!T11,"") -> 0 | AE12: =IF(OL!U$3=1,OL!U11,"") | AF12: =SUM(AC12:AE12) -> 0.002 | AG12: =IFERROR(F12-AC12,0) -> 0.005 | AH12: =IFERROR(G12-AD12,0) -> 0 | AI12: =IFERROR(H12-AE12,0) -> 0 | AJ12: =IFERROR(I12-AF12,0) -> 0.005 | AL12: =IF(LY!S$3=1,LY!S11,"") -> 0.008 | AM12: =IF(LY!T$3=1,LY!T11,"") | AN12: =IF(LY!U$3=1,LY!U11,"") | AO12: =SUM(AL12:AN12) -> 0.008 | AP12: =IFERROR(F12-AL12,0) -> -0.001 | AQ12: =IFERROR(G12-AM12,0) -> 0 | AR12: =IFERROR(H12-AN12,0) -> 0 | AS12: =IFERROR(I12-AO12,0) -> -0.001 | AU12: =Act!L11 -> 0 | AV12: =H12-AU12 -> #VALUE! | AX12: =IF('FC5+7'!S$3=1,'FC5+7'!S11,"") -> 0.007 | AY12: =IF('FC5+7'!T$3=1,'FC5+7'!T11,"") | AZ12: =IF('FC5+7'!U$3=1,'FC5+7'!U11,"") | BA12: =SUM(AX12:AZ12) -> 0.007 | BB12: =IFERROR(F12-AX12,0) -> 0 | BC12: =IFERROR(G12-AY12,0) -> 0 | BD12: =IFERROR(H12-AZ12,0) -> 0 | BE12: =IFERROR(I12-BA12,0) -> 0 | BG12: =F12 -> 0.007 | BH12: 0 | BI12: 0 | BJ12: =SUM(BG12:BI12) -> 0.007 | BK12: =IFERROR(F12-AC12,0) -> 0.005 | BL12: =IFERROR(G12-AD12,0) -> 0 | BM12: =IFERROR(AL12-AE12,0) -> 0 | BN12: =IFERROR(I12-BJ12,0) -> 0 | BP12: =F12 -> 0.007 | BQ12: =G12 | BR12: =#REF! -> #REF! | BS12: =SUM(BP12:BR12) -> #REF! | BT12: =BP12-AC12 -> 0.005 | BU12: =BQ12-AD12 -> #VALUE! | BV12: =BR12-AE12 -> #REF! | BW12: =BS12-AF12 -> #REF! | BY12: =H12-BR12 -> #VALUE! | CA12: ='FC2+10'!AA11 -> 0.032 | CC12: =CA12-I12 -> 0.025 | CE12: =IF('FC7+5'!S$3=1,'FC7+5'!S11,"") -> 0.007 | CF12: =IF('FC7+5'!T$3=1,'FC7+5'!T11,"") | CG12: =IF('FC7+5'!U$3=1,'FC7+5'!U11,"") | CH12: =SUM(CE12:CG12) -> 0.007 | CI12: =IFERROR(F12-CE12,0) -> 0 | CJ12: =IFERROR(G12-CF12,0) -> 0 | CK12: =IFERROR(H12-CG12,0) -> 0 | CL12: =IFERROR(I12-CH12,0) -> 0 | CM12: =IF('FC7+5'!AC$3=1,'FC7+5'!AC11,"") -> 0.061 | CN12: =I12-CM12 -> -0.054
C13: Wholesale volume (K units) To third party (Domestic) - DATSUN | F13: =IF(Act!S$3=1,Act!S12,"") -> 0 | G13: =IF(Act!T$3=1,Act!T12,"") | H13: =IF(Act!U$3=1,Act!U12,"") | I13: =SUM(F13:H13) -> 0 | K13: =IF(BP!S$3=1,BP!S12,"") -> 0 | L13: =IF(BP!T$3=1,BP!T12,"") | M13: =IF(BP!U$3=1,BP!U12,"") | N13: =SUM(K13:M13) -> 0 | O13: =IFERROR(F13-K13,0) -> 0 | P13: =IFERROR(G13-L13,0) -> 0 | Q13: =IFERROR(H13-M13,0) -> 0 | R13: =F13-K13 -> 0 | T13: =IF('FC2+10'!S$3=1,'FC2+10'!S12,"") -> 0 | U13: =IF('FC2+10'!T$3=1,'FC2+10'!T12,"") | V13: =IF('FC2+10'!U$3=1,'FC2+10'!U12,"") | W13: =SUM(T13:V13) -> 0 | X13: =IFERROR(F13-T13,0) -> 0 | Y13: =IFERROR(G13-U13,0) -> 0 | Z13: =IFERROR(H13-V13,0) -> 0 | AA13: =I13-W13 -> 0 | AC13: =IF(OL!S$3=1,OL!S12,"") -> 0 | AD13: =IF(OL!T$3=1,OL!T12,"") -> 0 | AE13: =IF(OL!U$3=1,OL!U12,"") | AF13: =SUM(AC13:AE13) -> 0 | AG13: =IFERROR(F13-AC13,0) -> 0 | AH13: =IFERROR(G13-AD13,0) -> 0 | AI13: =IFERROR(H13-AE13,0) -> 0 | AJ13: =IFERROR(I13-AF13,0) -> 0 | AL13: =IF(LY!S$3=1,LY!S12,"") -> 0 | AM13: =IF(LY!T$3=1,LY!T12,"") | AN13: =IF(LY!U$3=1,LY!U12,"") | AO13: =SUM(AL13:AN13) -> 0 | AP13: =IFERROR(F13-AL13,0) -> 0 | AQ13: =IFERROR(G13-AM13,0) -> 0 | AR13: =IFERROR(H13-AN13,0) -> 0 | AS13: =IFERROR(I13-AO13,0) -> 0 | AU13: =Act!L12 -> 0 | AV13: =H13-AU13 -> #VALUE! | AX13: =IF('FC5+7'!S$3=1,'FC5+7'!S12,"") -> 0 | AY13: =IF('FC5+7'!T$3=1,'FC5+7'!T12,"") | AZ13: =IF('FC5+7'!U$3=1,'FC5+7'!U12,"") | BA13: =SUM(AX13:AZ13) -> 0 | BB13: =IFERROR(F13-AX13,0) -> 0 | BC13: =IFERROR(G13-AY13,0) -> 0 | BD13: =IFERROR(H13-AZ13,0) -> 0 | BE13: =IFERROR(I13-BA13,0) -> 0 | BG13: =F13 -> 0 | BH13: 0 | BI13: 0 | BJ13: =SUM(BG13:BI13) -> 0 | BK13: =IFERROR(F13-AC13,0) -> 0 | BL13: =IFERROR(G13-AD13,0) -> 0 | BM13: =IFERROR(AL13-AE13,0) -> 0 | BN13: =IFERROR(I13-BJ13,0) -> 0 | BP13: =F13 -> 0 | BQ13: =G13 | BR13: =#REF! -> #REF! | BS13: =SUM(BP13:BR13) -> #REF! | BT13: =BP13-AC13 -> 0 | BU13: =BQ13-AD13 -> #VALUE! | BV13: =BR13-AE13 -> #REF! | BW13: =BS13-AF13 -> #REF! | BY13: =H13-BR13 -> #VALUE! | CA13: ='FC2+10'!AA12 -> 0 | CC13: =CA13-I13 -> 0 | CE13: =IF('FC7+5'!S$3=1,'FC7+5'!S12,"") -> 0 | CF13: =IF('FC7+5'!T$3=1,'FC7+5'!T12,"") | CG13: =IF('FC7+5'!U$3=1,'FC7+5'!U12,"") | CH13: =SUM(CE13:CG13) -> 0 | CI13: =IFERROR(F13-CE13,0) -> 0 | CJ13: =IFERROR(G13-CF13,0) -> 0 | CK13: =IFERROR(H13-CG13,0) -> 0 | CL13: =IFERROR(I13-CH13,0) -> 0 | CM13: =IF('FC7+5'!AC$3=1,'FC7+5'!AC12,"") -> 0 | CN13: =I13-CM13 -> 0
C14: Wholesale volume (K units) To third party (Export) | F14: =IF(Act!S$3=1,Act!S13,"") -> 0.481 | G14: =IF(Act!T$3=1,Act!T13,"") | H14: =IF(Act!U$3=1,Act!U13,"") | I14: =SUM(F14:H14) -> 0.481 | K14: =IF(BP!S$3=1,BP!S13,"") -> 1.062 | L14: =IF(BP!T$3=1,BP!T13,"") | M14: =IF(BP!U$3=1,BP!U13,"") | N14: =SUM(K14:M14) -> 1.062 | O14: =IFERROR(F14-K14,0) -> -0.581 | P14: =IFERROR(G14-L14,0) -> 0 | Q14: =IFERROR(H14-M14,0) -> 0 | R14: =F14-K14 -> -0.581 | T14: =IF('FC2+10'!S$3=1,'FC2+10'!S13,"") -> 0.481 | U14: =IF('FC2+10'!T$3=1,'FC2+10'!T13,"") | V14: =IF('FC2+10'!U$3=1,'FC2+10'!U13,"") | W14: =SUM(T14:V14) -> 0.481 | X14: =IFERROR(F14-T14,0) -> 0 | Y14: =IFERROR(G14-U14,0) -> 0 | Z14: =IFERROR(H14-V14,0) -> 0 | AA14: =I14-W14 -> 0 | AC14: =IF(OL!S$3=1,OL!S13,"") -> 0.349 | AD14: =IF(OL!T$3=1,OL!T13,"") -> 0.867 | AE14: =IF(OL!U$3=1,OL!U13,"") | AF14: =SUM(AC14:AE14) -> 1.216 | AG14: =IFERROR(F14-AC14,0) -> 0.132 | AH14: =IFERROR(G14-AD14,0) -> 0 | AI14: =IFERROR(H14-AE14,0) -> 0 | AJ14: =IFERROR(I14-AF14,0) -> -0.735 | AL14: =IF(LY!S$3=1,LY!S13,"") -> 1.903 | AM14: =IF(LY!T$3=1,LY!T13,"") | AN14: =IF(LY!U$3=1,LY!U13,"") | AO14: =SUM(AL14:AN14) -> 1.903 | AP14: =IFERROR(F14-AL14,0) -> -1.422 | AQ14: =IFERROR(G14-AM14,0) -> 0 | AR14: =IFERROR(H14-AN14,0) -> 0 | AS14: =IFERROR(I14-AO14,0) -> -1.422 | AU14: =Act!L13 -> 0.625 | AV14: =H14-AU14 -> #VALUE! | AX14: =IF('FC5+7'!S$3=1,'FC5+7'!S13,"") -> 0.481 | AY14: =IF('FC5+7'!T$3=1,'FC5+7'!T13,"") | AZ14: =IF('FC5+7'!U$3=1,'FC5+7'!U13,"") | BA14: =SUM(AX14:AZ14) -> 0.481 | BB14: =IFERROR(F14-AX14,0) -> 0 | BC14: =IFERROR(G14-AY14,0) -> 0 | BD14: =IFERROR(H14-AZ14,0) -> 0 | BE14: =IFERROR(I14-BA14,0) -> 0 | BG14: =F14 -> 0.481 | BH14: 0.867 | BI14: 1.045 | BJ14: =SUM(BG14:BI14) -> 2.393 | BK14: =IFERROR(F14-AC14,0) -> 0.132 | BL14: =IFERROR(G14-AD14,0) -> 0 | BM14: =IFERROR(AL14-AE14,0) -> 0 | BN14: =IFERROR(I14-BJ14,0) -> -1.912 | BP14: =F14 -> 0.481 | BQ14: =G14 | BR14: =#REF! -> #REF! | BS14: =SUM(BP14:BR14) -> #REF! | BT14: =BP14-AC14 -> 0.132 | BU14: =BQ14-AD14 -> #VALUE! | BV14: =BR14-AE14 -> #REF! | BW14: =BS14-AF14 -> #REF! | BY14: =H14-BR14 -> #VALUE! | CA14: ='FC2+10'!AA13 -> 2.686 | CC14: =CA14-I14 -> 2.205 | CE14: =IF('FC7+5'!S$3=1,'FC7+5'!S13,"") -> 0.481 | CF14: =IF('FC7+5'!T$3=1,'FC7+5'!T13,"") | CG14: =IF('FC7+5'!U$3=1,'FC7+5'!U13,"") | CH14: =SUM(CE14:CG14) -> 0.481 | CI14: =IFERROR(F14-CE14,0) -> 0 | CJ14: =IFERROR(G14-CF14,0) -> 0 | CK14: =IFERROR(H14-CG14,0) -> 0 | CL14: =IFERROR(I14-CH14,0) -> 0 | CM14: =IF('FC7+5'!AC$3=1,'FC7+5'!AC13,"") -> 2.384 | CN14: =I14-CM14 -> -1.903
BT15: =BP15-AC15 -> 0 | BU15: =BQ15-AD15 -> 0 | BV15: =BR15-AE15 -> 0 | BW15: =BS15-AF15 -> 0 | CC15: =CA15-I15 -> 0
BT16: =BP16-AC16 -> 0 | BU16: =BQ16-AD16 -> 0 | BV16: =BR16-AE16 -> 0 | BW16: =BS16-AF16 -> 0 | CC16: =CA16-I16 -> 0
D17: Gross Sales - New Vehicle (M&S function scope) | O17: =IFERROR(F17-K17,0) -> 0 | P17: =IFERROR(G17-L17,0) -> 0 | Q17: =IFERROR(H17-M17,0) -> 0 | R17: =I17-N17 -> 0 | X17: =IFERROR(F17-T17,0) -> 0 | Y17: =IFERROR(G17-U17,0) -> 0 | Z17: =IFERROR(H17-V17,0) -> 0 | AA17: =I17-W17 -> 0 | AE17: 0 | AG17: =IFERROR(F17-AC17,0) -> 0 | AH17: =IFERROR(G17-AD17,0) -> 0 | AI17: =IFERROR(H17-AE17,0) -> 0 | AJ17: =IFERROR(I17-AF17,0) -> 0 | AP17: =IFERROR(F17-AL17,0) -> 0 | AQ17: =IFERROR(G17-AM17,0) -> 0 | AR17: =IFERROR(H17-AN17,0) -> 0 | AS17: =IFERROR(I17-AO17,0) -> 0 | AU17: =Act!L16 -> 0 | AV17: =H17-AU17 -> 0 | BB17: =IFERROR(F17-AX17,0) -> 0 | BC17: =IFERROR(G17-AY17,0) -> 0 | BD17: =IFERROR(H17-AZ17,0) -> 0 | BE17: =IFERROR(I17-BA17,0) -> 0 | BG17: =F17 -> 0 | BK17: =IFERROR(F17-AC17,0) -> 0 | BL17: =IFERROR(G17-AD17,0) -> 0 | BM17: =IFERROR(AL17-AE17,0) -> 0 | BN17: =IFERROR(I17-BJ17,0) -> 0 | BP17: =F17 -> 0 | BQ17: =G17 -> 0 | BR17: =#REF! -> #REF! | BT17: =BP17-AC17 -> 0 | BU17: =BQ17-AD17 -> 0 | BV17: =BR17-AE17 -> #REF! | BW17: =BS17-AF17 -> 0 | BY17: =H17-BR17 -> #REF! | CA17: ='FC2+10'!AA16 -> 0 | CC17: =CA17-I17 -> 0 | CI17: =IFERROR(F17-CE17,0) -> 0 | CJ17: =IFERROR(G17-CF17,0) -> 0 | CK17: =IFERROR(H17-CG17,0) -> 0 | CL17: =IFERROR(I17-CH17,0) -> 0 | CN17: =I17-CM17 -> 0
D18: Gross Sales - Other External sales | O18: =IFERROR(F18-K18,0) -> 0 | P18: =IFERROR(G18-L18,0) -> 0 | Q18: =IFERROR(H18-M18,0) -> 0 | R18: =I18-N18 -> 0 | X18: =IFERROR(F18-T18,0) -> 0 | Y18: =IFERROR(G18-U18,0) -> 0 | Z18: =IFERROR(H18-V18,0) -> 0 | AA18: =I18-W18 -> 0 | AE18: 0 | AG18: =IFERROR(F18-AC18,0) -> 0 | AH18: =IFERROR(G18-AD18,0) -> 0 | AI18: =IFERROR(H18-AE18,0) -> 0 | AJ18: =IFERROR(I18-AF18,0) -> 0 | AP18: =IFERROR(F18-AL18,0) -> 0 | AQ18: =IFERROR(G18-AM18,0) -> 0 | AR18: =IFERROR(H18-AN18,0) -> 0 | AS18: =IFERROR(I18-AO18,0) -> 0 | AU18: =Act!L17 -> 0 | AV18: =H18-AU18 -> 0 | BB18: =IFERROR(F18-AX18,0) -> 0 | BC18: =IFERROR(G18-AY18,0) -> 0 | BD18: =IFERROR(H18-AZ18,0) -> 0 | BE18: =IFERROR(I18-BA18,0) -> 0 | BG18: =F18 -> 0 | BK18: =IFERROR(F18-AC18,0) -> 0 | BL18: =IFERROR(G18-AD18,0) -> 0 | BM18: =IFERROR(AL18-AE18,0) -> 0 | BN18: =IFERROR(I18-BJ18,0) -> 0 | BP18: =F18 -> 0 | BQ18: =G18 -> 0 | BR18: =#REF! -> #REF! | BT18: =BP18-AC18 -> 0 | BU18: =BQ18-AD18 -> 0 | BV18: =BR18-AE18 -> #REF! | BW18: =BS18-AF18 -> 0 | BY18: =H18-BR18 -> #REF! | CA18: ='FC2+10'!AA17 -> 0 | CC18: =CA18-I18 -> 0 | CI18: =IFERROR(F18-CE18,0) -> 0 | CJ18: =IFERROR(G18-CF18,0) -> 0 | CK18: =IFERROR(H18-CG18,0) -> 0 | CL18: =IFERROR(I18-CH18,0) -> 0 | CN18: =I18-CM18 -> 0
B19: Gross Sales | F19: =IF(Act!S$3=1,Act!S18,"") -> 612.22646 | G19: =IF(Act!T$3=1,Act!T18,"") | H19: =IF(Act!U$3=1,Act!U18,"") | I19: =SUM(F19:H19) -> 612.22646 | K19: =IF(BP!S$3=1,BP!S18,"") -> 647.19888 | L19: =IF(BP!T$3=1,BP!T18,"") | M19: =IF(BP!U$3=1,BP!U18,"") | N19: =SUM(K19:M19) -> 647.19888 | O19: =IFERROR(F19-K19,0) -> -34.972416 | P19: =IFERROR(G19-L19,0) -> 0 | Q19: =IFERROR(H19-M19,0) -> 0 | R19: =I19-N19 -> -34.972416 | T19: =IF('FC2+10'!S$3=1,'FC2+10'!S18,"") -> 612.22646 | U19: =IF('FC2+10'!T$3=1,'FC2+10'!T18,"") | V19: =IF('FC2+10'!U$3=1,'FC2+10'!U18,"") | W19: =SUM(T19:V19) -> 612.22646 | X19: =IFERROR(F19-T19,0) -> 0 | Y19: =IFERROR(G19-U19,0) -> 0 | Z19: =IFERROR(H19-V19,0) -> 0 | AA19: =I19-W19 -> 0 | AC19: =IF(OL!S$3=1,OL!S18,"") -> 867.43498 | AD19: =IF(OL!T$3=1,OL!T18,"") -> 998.88562 | AE19: =IF(OL!U$3=1,OL!U18,"") | AF19: =SUM(AC19:AE19) -> 1866.3206 | AG19: =IFERROR(F19-AC19,0) -> -255.20852 | AH19: =IFERROR(G19-AD19,0) -> 0 | AI19: =IFERROR(H19-AE19,0) -> 0 | AJ19: =IFERROR(I19-AF19,0) -> -1254.0941 | AL19: =IF(LY!S$3=1,LY!S18,"") -> 750.84895 | AM19: =IF(LY!T$3=1,LY!T18,"") | AN19: =IF(LY!U$3=1,LY!U18,"") | AO19: =SUM(AL19:AN19) -> 750.84895 | AP19: =IFERROR(F19-AL19,0) -> -138.62249 | AQ19: =IFERROR(G19-AM19,0) -> 0 | AR19: =IFERROR(H19-AN19,0) -> 0 | AS19: =IFERROR(I19-AO19,0) -> -138.62249 | AU19: =Act!L18 -> 972.88696 | AV19: =H19-AU19 -> #VALUE! | AX19: =IF('FC5+7'!S$3=1,'FC5+7'!S18,"") -> 612.22646 | AY19: =IF('FC5+7'!T$3=1,'FC5+7'!T18,"") | AZ19: =IF('FC5+7'!U$3=1,'FC5+7'!U18,"") | BA19: =SUM(AX19:AZ19) -> 612.22646 | BB19: =IFERROR(F19-AX19,0) -> 0 | BC19: =IFERROR(G19-AY19,0) -> 0 | BD19: =IFERROR(H19-AZ19,0) -> 0 | BE19: =IFERROR(I19-BA19,0) -> 0 | BG19: =F19 -> 612.22646 | BH19: 710.14442 | BI19: 1097.4923 | BJ19: =SUM(BG19:BI19) -> 2419.8632 | BK19: =IFERROR(F19-AC19,0) -> -255.20852 | BL19: =IFERROR(G19-AD19,0) -> 0 | BM19: =IFERROR(AL19-AE19,0) -> 0 | BN19: =IFERROR(I19-BJ19,0) -> -1807.6367 | BP19: =F19 -> 612.22646 | BQ19: =G19 | BR19: =#REF! -> #REF! | BS19: =SUM(BP19:BR19) -> #REF! | BT19: =BP19-AC19 -> -255.20852 | BU19: =BQ19-AD19 -> #VALUE! | BV19: =BR19-AE19 -> #REF! | BW19: =BS19-AF19 -> #REF! | BY19: =H19-BR19 -> #VALUE! | CA19: ='FC2+10'!AA18 -> 2654.6861 | CC19: =CA19-I19 -> 2042.4597 | CE19: =IF('FC7+5'!S$3=1,'FC7+5'!S18,"") -> 612.22646 | CF19: =IF('FC7+5'!T$3=1,'FC7+5'!T18,"") | CG19: =IF('FC7+5'!U$3=1,'FC7+5'!U18,"") | CH19: =SUM(CE19:CG19) -> 612.22646 | CI19: =IFERROR(F19-CE19,0) -> 0 | CJ19: =IFERROR(G19-CF19,0) -> 0 | CK19: =IFERROR(H19-CG19,0) -> 0 | CL19: =IFERROR(I19-CH19,0) -> 0 | CM19: =IF('FC7+5'!AC$3=1,'FC7+5'!AC18,"") -> 3313.6771 | CN19: =I19-CM19 -> -2701.4507
D20: VME - New Vehicle (M&S function scope) | O20: =IFERROR(F20-K20,0) -> 0 | P20: =IFERROR(G20-L20,0) -> 0 | Q20: =IFERROR(H20-M20,0) -> 0 | R20: =I20-N20 -> 0 | X20: =IFERROR(F20-T20,0) -> 0 | Y20: =IFERROR(G20-U20,0) -> 0 | Z20: =IFERROR(H20-V20,0) -> 0 | AA20: =I20-W20 -> 0 | AE20: 0 | AG20: =IFERROR(F20-AC20,0) -> 0 | AH20: =IFERROR(G20-AD20,0) -> 0 | AI20: =IFERROR(H20-AE20,0) -> 0 | AJ20: =IFERROR(I20-AF20,0) -> 0 | AP20: =IFERROR(F20-AL20,0) -> 0 | AQ20: =IFERROR(G20-AM20,0) -> 0 | AR20: =IFERROR(H20-AN20,0) -> 0 | AS20: =IFERROR(I20-AO20,0) -> 0 | AU20: =Act!L19 -> 0 | AV20: =H20-AU20 -> 0 | BB20: =IFERROR(F20-AX20,0) -> 0 | BC20: =IFERROR(G20-AY20,0) -> 0 | BD20: =IFERROR(H20-AZ20,0) -> 0 | BE20: =IFERROR(I20-BA20,0) -> 0 | BG20: =F20 -> 0 | BK20: =IFERROR(F20-AC20,0) -> 0 | BN20: =IFERROR(I20-BJ20,0) -> 0 | BT20: =BP20-AC20 -> 0 | BU20: =BQ20-AD20 -> 0 | BV20: =BR20-AE20 -> 0 | BW20: =BS20-AF20 -> 0 | BY20: =H20-BR20 -> 0 | CA20: ='FC2+10'!AA19 -> 0 | CC20: =CA20-I20 -> 0 | CI20: =IFERROR(F20-CE20,0) -> 0 | CJ20: =IFERROR(G20-CF20,0) -> 0 | CK20: =IFERROR(H20-CG20,0) -> 0 | CL20: =IFERROR(I20-CH20,0) -> 0 | CN20: =I20-CM20 -> 0
D21: VME - Other | O21: =IFERROR(F21-K21,0) -> 0 | P21: =IFERROR(G21-L21,0) -> 0 | Q21: =IFERROR(H21-M21,0) -> 0 | R21: =I21-N21 -> 0 | X21: =IFERROR(F21-T21,0) -> 0 | Y21: =IFERROR(G21-U21,0) -> 0 | Z21: =IFERROR(H21-V21,0) -> 0 | AA21: =I21-W21 -> 0 | AE21: 0 | AG21: =IFERROR(F21-AC21,0) -> 0 | AH21: =IFERROR(G21-AD21,0) -> 0 | AI21: =IFERROR(H21-AE21,0) -> 0 | AJ21: =IFERROR(I21-AF21,0) -> 0 | AP21: =IFERROR(F21-AL21,0) -> 0 | AQ21: =IFERROR(G21-AM21,0) -> 0 | AR21: =IFERROR(H21-AN21,0) -> 0 | AS21: =IFERROR(I21-AO21,0) -> 0 | AU21: =Act!L20 -> 0 | AV21: =H21-AU21 -> 0 | BB21: =IFERROR(F21-AX21,0) -> 0 | BC21: =IFERROR(G21-AY21,0) -> 0 | BD21: =IFERROR(H21-AZ21,0) -> 0 | BE21: =IFERROR(I21-BA21,0) -> 0 | BG21: =F21 -> 0 | BK21: =IFERROR(F21-AC21,0) -> 0 | BN21: =IFERROR(I21-BJ21,0) -> 0 | BT21: =BP21-AC21 -> 0 | BU21: =BQ21-AD21 -> 0 | BV21: =BR21-AE21 -> 0 | BW21: =BS21-AF21 -> 0 | BY21: =H21-BR21 -> 0 | CA21: ='FC2+10'!AA20 -> 0 | CC21: =CA21-I21 -> 0 | CI21: =IFERROR(F21-CE21,0) -> 0 | CJ21: =IFERROR(G21-CF21,0) -> 0 | CK21: =IFERROR(H21-CG21,0) -> 0 | CL21: =IFERROR(I21-CH21,0) -> 0 | CN21: =I21-CM21 -> 0
C22: VME Total | F22: =IF(Act!S$3=1,Act!S21,"") -> -85.285283 | G22: =IF(Act!T$3=1,Act!T21,"") | H22: =IF(Act!U$3=1,Act!U21,"") | I22: =SUM(F22:H22) -> -85.285283 | K22: =IF(BP!S$3=1,BP!S21,"") -> -76.406511 | L22: =IF(BP!T$3=1,BP!T21,"") | M22: =IF(BP!U$3=1,BP!U21,"") | N22: =SUM(K22:M22) -> -76.406511 | O22: =IFERROR(F22-K22,0) -> -8.8787725 | P22: =IFERROR(G22-L22,0) -> 0 | Q22: =IFERROR(H22-M22,0) -> 0 | R22: =I22-N22 -> -8.8787725 | T22: =IF('FC2+10'!S$3=1,'FC2+10'!S21,"") -> -85.285283 | U22: =IF('FC2+10'!T$3=1,'FC2+10'!T21,"") | V22: =IF('FC2+10'!U$3=1,'FC2+10'!U21,"") | W22: =SUM(T22:V22) -> -85.285283 | X22: =IFERROR(F22-T22,0) -> 0 | Y22: =IFERROR(G22-U22,0) -> 0 | Z22: =IFERROR(H22-V22,0) -> 0 | AA22: =I22-W22 -> 0 | AC22: =IF(OL!S$3=1,OL!S21,"") -> -134.42478 | AD22: =IF(OL!T$3=1,OL!T21,"") -> -142.08356 | AE22: =IF(OL!U$3=1,OL!U21,"") | AF22: =SUM(AC22:AE22) -> -276.50834 | AG22: =IFERROR(F22-AC22,0) -> 49.139495 | AH22: =IFERROR(G22-AD22,0) -> 0 | AI22: =IFERROR(H22-AE22,0) -> 0 | AJ22: =IFERROR(I22-AF22,0) -> 191.22306 | AL22: =IF(LY!S$3=1,LY!S21,"") -> -97.808222 | AM22: =IF(LY!T$3=1,LY!T21,"") | AN22: =IF(LY!U$3=1,LY!U21,"") | AO22: =SUM(AL22:AN22) -> -97.808222 | AP22: =IFERROR(F22-AL22,0) -> 12.522939 | AQ22: =IFERROR(G22-AM22,0) -> 0 | AR22: =IFERROR(H22-AN22,0) -> 0 | AS22: =IFERROR(I22-AO22,0) -> 12.522939 | AU22: =Act!L21 -> -142.95643 | AV22: =H22-AU22 -> #VALUE! | AX22: =IF('FC5+7'!S$3=1,'FC5+7'!S21,"") -> -85.285283 | AY22: =IF('FC5+7'!T$3=1,'FC5+7'!T21,"") | AZ22: =IF('FC5+7'!U$3=1,'FC5+7'!U21,"") | BA22: =SUM(AX22:AZ22) -> -85.285283 | BB22: =IFERROR(F22-AX22,0) -> 0 | BC22: =IFERROR(G22-AY22,0) -> 0 | BD22: =IFERROR(H22-AZ22,0) -> 0 | BE22: =IFERROR(I22-BA22,0) -> 0 | BG22: =F22 -> -85.285283 | BH22: -95.106208 | BI22: -169.78057 | BJ22: =SUM(BG22:BI22) -> -350.17207 | BK22: =IFERROR(F22-AC22,0) -> 49.139495 | BL22: =IFERROR(G22-AD22,0) -> 0 | BM22: =IFERROR(AL22-AE22,0) -> 0 | BN22: =IFERROR(I22-BJ22,0) -> 264.88678 | BP22: =F22 -> -85.285283 | BQ22: =G22 | BR22: =#REF! -> #REF! | BS22: =SUM(BP22:BR22) -> #REF! | BT22: =BP22-AC22 -> 49.139495 | BU22: =BQ22-AD22 -> #VALUE! | BV22: =BR22-AE22 -> #REF! | BW22: =BS22-AF22 -> #REF! | BY22: =H22-BR22 -> #VALUE! | CA22: ='FC2+10'!AA21 -> -372.76108 | CC22: =CA22-I22 -> -287.4758 | CE22: =IF('FC7+5'!S$3=1,'FC7+5'!S21,"") -> -85.285283 | CF22: =IF('FC7+5'!T$3=1,'FC7+5'!T21,"") | CG22: =IF('FC7+5'!U$3=1,'FC7+5'!U21,"") | CH22: =SUM(CE22:CG22) -> -85.285283 | CI22: =IFERROR(F22-CE22,0) -> 0 | CJ22: =IFERROR(G22-CF22,0) -> 0 | CK22: =IFERROR(H22-CG22,0) -> 0 | CL22: =IFERROR(I22-CH22,0) -> 0 | CM22: =IF('FC7+5'!AC$3=1,'FC7+5'!AC21,"") -> -481.20338 | CN22: =I22-CM22 -> 395.9181
B23: Net Sales | F23: =SUM(F19,F22) -> 526.94118 | G23: =SUM(G19,G22) -> 0 | H23: =SUM(H19,H22) -> 0 | I23: =SUM(F23:H23) -> 526.94118 | K23: =SUM(K19,K22) -> 570.79237 | L23: =SUM(L19,L22) -> 0 | M23: =SUM(M19,M22) -> 0 | N23: =SUM(K23:M23) -> 570.79237 | O23: =IFERROR(F23-K23,0) -> -43.851189 | P23: =IFERROR(G23-L23,0) -> 0 | Q23: =IFERROR(H23-M23,0) -> 0 | R23: =I23-N23 -> -43.851189 | T23: =SUM(T19,T22) -> 526.94118 | U23: =SUM(U19,U22) -> 0 | V23: =SUM(V19,V22) -> 0 | W23: =SUM(T23:V23) -> 526.94118 | X23: =IFERROR(F23-T23,0) -> 0 | Y23: =IFERROR(G23-U23,0) -> 0 | Z23: =IFERROR(H23-V23,0) -> 0 | AA23: =I23-W23 -> 0 | AC23: =SUM(AC19,AC22) -> 733.0102 | AD23: =SUM(AD19,AD22) -> 856.80206 | AE23: =SUM(AE19,AE22) -> 0 | AF23: =SUM(AC23:AE23) -> 1589.8123 | AG23: =IFERROR(F23-AC23,0) -> -206.06903 | AH23: =IFERROR(G23-AD23,0) -> -856.80206 | AI23: =IFERROR(H23-AE23,0) -> 0 | AJ23: =IFERROR(I23-AF23,0) -> -1062.8711 | AL23: =SUM(AL19,AL22) -> 653.04073 | AM23: =SUM(AM19,AM22) -> 0 | AN23: =SUM(AN19,AN22) -> 0 | AO23: =SUM(AL23:AN23) -> 653.04073 | AP23: =IFERROR(F23-AL23,0) -> -126.09955 | AQ23: =IFERROR(G23-AM23,0) -> 0 | AR23: =IFERROR(H23-AN23,0) -> 0 | AS23: =IFERROR(I23-AO23,0) -> -126.09955 | AU23: =Act!L22 -> 829.93053 | AV23: =H23-AU23 -> -829.93053 | AX23: =SUM(AX19,AX22) -> 526.94118 | AY23: =SUM(AY19,AY22) -> 0 | AZ23: =SUM(AZ19,AZ22) -> 0 | BA23: =SUM(AX23:AZ23) -> 526.94118 | BB23: =IFERROR(F23-AX23,0) -> 0 | BC23: =IFERROR(G23-AY23,0) -> 0 | BD23: =IFERROR(H23-AZ23,0) -> 0 | BE23: =IFERROR(I23-BA23,0) -> 0 | BG23: =F23 -> 526.94118 | BH23: 615.03821 | BI23: 927.71175 | BJ23: =SUM(BG23:BI23) -> 2069.6911 | BK23: =IFERROR(F23-AC23,0) -> -206.06903 | BL23: =IFERROR(G23-AD23,0) -> -856.80206 | BM23: =IFERROR(AL23-AE23,0) -> 653.04073 | BN23: =IFERROR(I23-BJ23,0) -> -1542.75 | BP23: =F23 -> 526.94118 | BQ23: =G23 -> 0 | BR23: =#REF! -> #REF! | BS23: =SUM(BP23:BR23) -> #REF! | BT23: =BP23-AC23 -> -206.06903 | BU23: =BQ23-AD23 -> -856.80206 | BV23: =BR23-AE23 -> #REF! | BW23: =BS23-AF23 -> #REF! | BY23: =H23-BR23 -> #REF! | CA23: ='FC2+10'!AA22 -> 2281.9251 | CC23: =CA23-I23 -> 1754.9839 | CE23: =SUM(CE19,CE22) -> 526.94118 | CF23: =SUM(CF19,CF22) -> 0 | CG23: =SUM(CG19,CG22) -> 0 | CH23: =SUM(CE23:CG23) -> 526.94118 | CI23: =IFERROR(F23-CE23,0) -> 0 | CJ23: =IFERROR(G23-CF23,0) -> 0 | CK23: =IFERROR(H23-CG23,0) -> 0 | CL23: =IFERROR(I23-CH23,0) -> 0 | CM23: =SUM(CM19,CM22) -> 2832.4737 | CN23: =I23-CM23 -> -2305.5326
D24: @Std. Cost | O24: =IFERROR(F24-K24,0) -> 0 | P24: =IFERROR(G24-L24,0) -> 0 | Q24: =IFERROR(H24-M24,0) -> 0 | R24: =I24-N24 -> 0 | X24: =IFERROR(F24-T24,0) -> 0 | Y24: =IFERROR(G24-U24,0) -> 0 | Z24: =IFERROR(H24-V24,0) -> 0 | AA24: =I24-W24 -> 0 | AE24: 0 | AG24: =IFERROR(F24-AC24,0) -> 0 | AH24: =IFERROR(G24-AD24,0) -> 0 | AI24: =IFERROR(H24-AE24,0) -> 0 | AJ24: =IFERROR(I24-AF24,0) -> 0 | AP24: =IFERROR(F24-AL24,0) -> 0 | AQ24: =IFERROR(G24-AM24,0) -> 0 | AR24: =IFERROR(H24-AN24,0) -> 0 | AS24: =IFERROR(I24-AO24,0) -> 0 | AU24: =Act!L23 -> 0 | AV24: =H24-AU24 -> 0 | BN24: =IFERROR(I24-BJ24,0) -> 0 | BT24: =BP24-AC24 -> 0 | BU24: =BQ24-AD24 -> 0 | BV24: =BR24-AE24 -> 0 | BW24: =BS24-AF24 -> 0 | BY24: =H24-BR24 -> 0 | CA24: ='FC2+10'!AA23 -> 0 | CC24: =CA24-I24 -> 0 | CN24: =I24-CM24 -> 0
D25: Other MFG variable | O25: =IFERROR(F25-K25,0) -> 0 | P25: =IFERROR(G25-L25,0) -> 0 | Q25: =IFERROR(H25-M25,0) -> 0 | R25: =I25-N25 -> 0 | X25: =IFERROR(F25-T25,0) -> 0 | Y25: =IFERROR(G25-U25,0) -> 0 | Z25: =IFERROR(H25-V25,0) -> 0 | AA25: =I25-W25 -> 0 | AE25: 0 | AG25: =IFERROR(F25-AC25,0) -> 0 | AH25: =IFERROR(G25-AD25,0) -> 0 | AI25: =IFERROR(H25-AE25,0) -> 0 | AJ25: =IFERROR(I25-AF25,0) -> 0 | AP25: =IFERROR(F25-AL25,0) -> 0 | AQ25: =IFERROR(G25-AM25,0) -> 0 | AR25: =IFERROR(H25-AN25,0) -> 0 | AS25: =IFERROR(I25-AO25,0) -> 0 | AU25: =Act!L24 -> 0 | AV25: =H25-AU25 -> 0 | BN25: =IFERROR(I25-BJ25,0) -> 0 | BT25: =BP25-AC25 -> 0 | BU25: =BQ25-AD25 -> 0 | BV25: =BR25-AE25 -> 0 | BW25: =BS25-AF25 -> 0 | BY25: =H25-BR25 -> 0 | CA25: ='FC2+10'!AA24 -> 0 | CC25: =CA25-I25 -> 0 | CN25: =I25-CM25 -> 0
C26: Parts / Materials and Others | F26: =IF(Act!S$3=1,Act!S25,"") -> -440.85756 | G26: =IF(Act!T$3=1,Act!T25,"") | H26: =IF(Act!U$3=1,Act!U25,"") | I26: =SUM(F26:H26) -> -440.85756 | K26: =IF(BP!S$3=1,BP!S25,"") -> -483.27574 | L26: =IF(BP!T$3=1,BP!T25,"") | M26: =IF(BP!U$3=1,BP!U25,"") | N26: =SUM(K26:M26) -> -483.27574 | O26: =IFERROR(F26-K26,0) -> 42.418181 | P26: =IFERROR(G26-L26,0) -> 0 | Q26: =IFERROR(H26-M26,0) -> 0 | R26: =I26-N26 -> 42.418181 | T26: =IF('FC2+10'!S$3=1,'FC2+10'!S25,"") -> #VALUE! | U26: =IF('FC2+10'!T$3=1,'FC2+10'!T25,"") | V26: =IF('FC2+10'!U$3=1,'FC2+10'!U25,"") | W26: =SUM(T26:V26) -> #VALUE! | X26: =IFERROR(F26-T26,0) -> 0 | Y26: =IFERROR(G26-U26,0) -> 0 | Z26: =IFERROR(H26-V26,0) -> 0 | AA26: =I26-W26 -> #VALUE! | AC26: =IF(OL!S$3=1,OL!S25,"") -> -588.72719 | AD26: =IF(OL!T$3=1,OL!T25,"") -> -715.65292 | AE26: =IF(OL!U$3=1,OL!U25,"") | AF26: =SUM(AC26:AE26) -> -1304.3801 | AG26: =IFERROR(F26-AC26,0) -> 147.86963 | AH26: =IFERROR(G26-AD26,0) -> 0 | AI26: =IFERROR(H26-AE26,0) -> 0 | AJ26: =IFERROR(I26-AF26,0) -> 863.52256 | AL26: =IF(LY!S$3=1,LY!S25,"") -> -496.47291 | AM26: =IF(LY!T$3=1,LY!T25,"") | AN26: =IF(LY!U$3=1,LY!U25,"") | AO26: =SUM(AL26:AN26) -> -496.47291 | AP26: =IFERROR(F26-AL26,0) -> 55.615353 | AQ26: =IFERROR(G26-AM26,0) -> 0 | AR26: =IFERROR(H26-AN26,0) -> 0 | AS26: =IFERROR(I26-AO26,0) -> 55.615353 | AU26: =Act!L25 -> -693.35565 | AV26: =H26-AU26 -> #VALUE! | AX26: =IF('FC5+7'!S$3=1,'FC5+7'!S25,"") -> -440.85756 | AY26: =IF('FC5+7'!T$3=1,'FC5+7'!T25,"") | AZ26: =IF('FC5+7'!U$3=1,'FC5+7'!U25,"") | BA26: =SUM(AX26:AZ26) -> -440.85756 | BB26: =IFERROR(F26-AX26,0) -> 0 | BC26: =IFERROR(G26-AY26,0) -> 0 | BD26: =IFERROR(H26-AZ26,0) -> 0 | BE26: =IFERROR(I26-BA26,0) -> 0 | BG26: =F26 -> -440.85756 | BH26: -492.24093 | BI26: -857.4071 | BJ26: =SUM(BG26:BI26) -> -1790.5056 | BK26: =IFERROR(F26-AC26,0) -> 147.86963 | BL26: =IFERROR(G26-AD26,0) -> 0 | BM26: =IFERROR(AL26-AE26,0) -> 0 | BN26: =IFERROR(I26-BJ26,0) -> 1349.648 | BP26: =F26 -> -440.85756 | BQ26: =G26 | BR26: =#REF! -> #REF! | BS26: =SUM(BP26:BR26) -> #REF! | BT26: =BP26-AC26 -> 147.86963 | BU26: =BQ26-AD26 -> #VALUE! | BV26: =BR26-AE26 -> #REF! | BW26: =BS26-AF26 -> #REF! | BY26: =H26-BR26 -> #VALUE! | CA26: ='FC2+10'!AA25 -> #VALUE! | CC26: =CA26-I26 -> #VALUE! | CE26: =IF('FC7+5'!S$3=1,'FC7+5'!S25,"") -> -440.85756 | CF26: =IF('FC7+5'!T$3=1,'FC7+5'!T25,"") | CG26: =IF('FC7+5'!U$3=1,'FC7+5'!U25,"") | CH26: =SUM(CE26:CG26) -> -440.85756 | CI26: =IFERROR(F26-CE26,0) -> 0 | CJ26: =IFERROR(G26-CF26,0) -> 0 | CK26: =IFERROR(H26-CG26,0) -> 0 | CL26: =IFERROR(I26-CH26,0) -> 0 | CM26: =IF('FC7+5'!AC$3=1,'FC7+5'!AC25,"") -> -2272.6964 | CN26: =I26-CM26 -> 1831.8389
B27: CMP-I | F27: =SUM(F23,F26) -> 86.08362 | G27: =SUM(G23,G26) -> 0 | H27: =SUM(H23,H26) -> 0 | I27: =SUM(F27:H27) -> 86.08362 | K27: =K23+K26 -> 87.516627 | L27: =SUM(L23,L26) -> 0 | M27: =SUM(M23,M26) -> 0 | N27: =SUM(K27:M27) -> 87.516627 | O27: =IFERROR(F27-K27,0) -> -1.4330078 | P27: =IFERROR(G27-L27,0) -> 0 | Q27: =IFERROR(H27-M27,0) -> 0 | R27: =I27-N27 -> -1.4330078 | T27: =T23+T26 -> #VALUE! | U27: =SUM(U23,U26) -> 0 | V27: =SUM(V23,V26) -> 0 | W27: =SUM(T27:V27) -> #VALUE! | X27: =IFERROR(F27-T27,0) -> 0 | Y27: =IFERROR(G27-U27,0) -> 0 | Z27: =IFERROR(H27-V27,0) -> 0 | AA27: =I27-W27 -> #VALUE! | AC27: =AC23+AC26 -> 144.28301 | AD27: =SUM(AD23,AD26) -> 141.14914 | AE27: =SUM(AE23,AE26) -> 0 | AF27: =SUM(AC27:AE27) -> 285.43215 | AG27: =IFERROR(F27-AC27,0) -> -58.199392 | AH27: =IFERROR(G27-AD27,0) -> -141.14914 | AI27: =IFERROR(H27-AE27,0) -> 0 | AJ27: =IFERROR(I27-AF27,0) -> -199.34853 | AL27: =AL23+AL26 -> 156.56782 | AM27: =SUM(AM23,AM26) -> 0 | AN27: =SUM(AN23,AN26) -> 0 | AO27: =SUM(AL27:AN27) -> 156.56782 | AP27: =IFERROR(F27-AL27,0) -> -70.484198 | AQ27: =IFERROR(G27-AM27,0) -> 0 | AR27: =IFERROR(H27-AN27,0) -> 0 | AS27: =IFERROR(I27-AO27,0) -> -70.484198 | AU27: =Act!L26 -> 136.57489 | AV27: =H27-AU27 -> -136.57489 | AX27: =AX23+AX26 -> 86.08362 | AY27: =SUM(AY23,AY26) -> 0 | AZ27: =SUM(AZ23,AZ26) -> 0 | BA27: =SUM(AX27:AZ27) -> 86.08362 | BB27: =IFERROR(F27-AX27,0) -> 0 | BC27: =IFERROR(G27-AY27,0) -> 0 | BD27: =IFERROR(H27-AZ27,0) -> 0 | BE27: =IFERROR(I27-BA27,0) -> 0 | BG27: =F27 -> 86.08362 | BH27: 122.79728 | BI27: 70.304648 | BJ27: =SUM(BG27:BI27) -> 279.18555 | BK27: =IFERROR(F27-AC27,0) -> -58.199392 | BL27: =IFERROR(G27-AD27,0) -> -141.14914 | BM27: =IFERROR(AL27-AE27,0) -> 156.56782 | BN27: =IFERROR(I27-BJ27,0) -> -193.10193 | BP27: =F27 -> 86.08362 | BQ27: =G27 -> 0 | BR27: =#REF! -> #REF! | BS27: =SUM(BP27:BR27) -> #REF! | BT27: =BP27-AC27 -> -58.199392 | BU27: =BQ27-AD27 -> -141.14914 | BV27: =BR27-AE27 -> #REF! | BW27: =BS27-AF27 -> #REF! | BY27: =H27-BR27 -> #REF! | CA27: ='FC2+10'!AA26 -> #VALUE! | CC27: =CA27-I27 -> #VALUE! | CE27: =CE23+CE26 -> 86.08362 | CF27: =SUM(CF23,CF26) -> 0 | CG27: =SUM(CG23,CG26) -> 0 | CH27: =SUM(CE27:CG27) -> 86.08362 | CI27: =IFERROR(F27-CE27,0) -> 0 | CJ27: =IFERROR(G27-CF27,0) -> 0 | CK27: =IFERROR(H27-CG27,0) -> 0 | CL27: =IFERROR(I27-CH27,0) -> 0 | CM27: =CM23+CM26 -> 559.77731 | CN27: =I27-CM27 -> -473.69369
C28: % of Gross Sales | F28: =F27/F19 -> 0.14060748 | G28: =G27/G19 -> #VALUE! | H28: =H27/H19 -> #VALUE! | I28: =I27/I19 -> 0.14060748 | K28: =K27/K19 -> 0.1352237 | L28: =L27/L19 -> #VALUE! | M28: =M27/M19 -> #VALUE! | N28: =N27/N19 -> 0.1352237 | O28: =IFERROR(F28-K28,0) -> 0.0053837787 | P28: =IFERROR(G28-L28,0) -> 0 | Q28: =IFERROR(H28-M28,0) -> 0 | R28: =I28-N28 -> 0.0053837787 | T28: =T27/T19 -> #VALUE! | U28: =U27/U19 -> #VALUE! | V28: =V27/V19 -> #VALUE! | W28: =W27/W19 -> #VALUE! | X28: =IFERROR(F28-T28,0) -> 0 | Y28: =IFERROR(G28-U28,0) -> 0 | Z28: =IFERROR(H28-V28,0) -> 0 | AA28: =I28-W28 -> #VALUE! | AC28: =AC27/AC19 -> 0.16633294 | AD28: =AD27/AD19 -> 0.1413066 | AE28: =AE27/AE19 -> #VALUE! | AF28: =AF27/AF19 -> 0.15293843 | AG28: =IFERROR(F28-AC28,0) -> -0.025725461 | AH28: =IFERROR(G28-AD28,0) -> 0 | AI28: =IFERROR(H28-AE28,0) -> 0 | AJ28: =IFERROR(I28-AF28,0) -> -0.012330953 | AL28: =AL27/AL19 -> 0.20852106 | AM28: =AM27/AM19 -> #VALUE! | AN28: =AN27/AN19 -> #VALUE! | AO28: =AO27/AO19 -> 0.20852106 | AP28: =IFERROR(F28-AL28,0) -> -0.067913578 | AQ28: =IFERROR(G28-AM28,0) -> 0 | AR28: =IFERROR(H28-AN28,0) -> 0 | AS28: =IFERROR(I28-AO28,0) -> -0.067913578 | AU28: =Act!L27 -> 0.14038105 | AV28: =H28-AU28 -> #VALUE! | AX28: =AX27/AX19 -> 0.14060748 | AY28: =AY27/AY19 -> #VALUE! | AZ28: =AZ27/AZ19 -> #VALUE! | BA28: =BA27/BA19 -> 0.14060748 | BB28: =IFERROR(F28-AX28,0) -> 0 | BC28: =IFERROR(G28-AY28,0) -> 0 | BD28: =IFERROR(H28-AZ28,0) -> 0 | BE28: =IFERROR(I28-BA28,0) -> 0 | BG28: =F28 -> 0.14060748 | BH28: 0.17291874 | BI28: 0.064059353 | BJ28: =BJ27/BJ19 -> 0.11537245 | BK28: =IFERROR(F28-AC28,0) -> -0.025725461 | BL28: =IFERROR(G28-AD28,0) -> 0 | BM28: =IFERROR(AL28-AE28,0) -> 0 | BN28: =IFERROR(I28-BJ28,0) -> 0.025235029 | BP28: =F28 -> 0.14060748 | BQ28: =G28 -> #VALUE! | BR28: =#REF! -> #REF! | BS28: =BS27/BS19 -> #REF! | BT28: =BP28-AC28 -> -0.025725461 | BU28: =BQ28-AD28 -> #VALUE! | BV28: =BR28-AE28 -> #REF! | BW28: =BS28-AF28 -> #REF! | BY28: =H28-BR28 -> #VALUE! | CA28: ='FC2+10'!AA27 -> 0 | CC28: =CA28-I28 -> -0.14060748 | CE28: =CE27/CE19 -> 0.14060748 | CF28: =CF27/CF19 -> #VALUE! | CG28: =CG27/CG19 -> #VALUE! | CH28: =CH27/CH19 -> 0.14060748 | CI28: =IFERROR(F28-CE28,0) -> 0 | CJ28: =IFERROR(G28-CF28,0) -> 0 | CK28: =IFERROR(H28-CG28,0) -> 0 | CL28: =IFERROR(I28-CH28,0) -> 0 | CM28: =CM27/CM19 -> 0.16892935 | CN28: =I28-CM28 -> -0.028321868
D29: MFG | F29: =IF(Act!S$3=1,Act!S28,"") -> -29.170027 | G29: =IF(Act!T$3=1,Act!T28,"") | H29: =IF(Act!U$3=1,Act!U28,"") | I29: =SUM(F29:H29) -> -29.170027 | K29: =IF(BP!S$3=1,BP!S28,"") -> -30.77683 | L29: =IF(BP!T$3=1,BP!T28,"") | M29: =IF(BP!U$3=1,BP!U28,"") | N29: =SUM(K29:M29) -> -30.77683 | O29: =IFERROR(F29-K29,0) -> 1.6068029 | P29: =IFERROR(G29-L29,0) -> 0 | Q29: =IFERROR(H29-M29,0) -> 0 | R29: =I29-N29 -> 1.6068029 | T29: =IF('FC2+10'!S$3=1,'FC2+10'!S28,"") -> -29.170027 | U29: =IF('FC2+10'!T$3=1,'FC2+10'!T28,"") | V29: =IF('FC2+10'!U$3=1,'FC2+10'!U28,"") | W29: =SUM(T29:V29) -> -29.170027 | X29: =IFERROR(F29-T29,0) -> 0 | Y29: =IFERROR(G29-U29,0) -> 0 | Z29: =IFERROR(H29-V29,0) -> 0 | AA29: =I29-W29 -> 0 | AC29: =IF(OL!S$3=1,OL!S28,"") -> -26.61244 | AD29: =IF(OL!T$3=1,OL!T28,"") -> -27.002141 | AE29: =IF(OL!U$3=1,OL!U28,"") | AF29: =SUM(AC29:AE29) -> -53.614581 | AG29: =IFERROR(F29-AC29,0) -> -2.5575875 | AH29: =IFERROR(G29-AD29,0) -> 0 | AI29: =IFERROR(H29-AE29,0) -> 0 | AJ29: =IFERROR(I29-AF29,0) -> 24.444554 | AL29: =IF(LY!S$3=1,LY!S28,"") -> -28.523004 | AM29: =IF(LY!T$3=1,LY!T28,"") | AN29: =IF(LY!U$3=1,LY!U28,"") | AO29: =SUM(AL29:AN29) -> -28.523004 | AP29: =IFERROR(F29-AL29,0) -> -0.64702384 | AQ29: =IFERROR(G29-AM29,0) -> 0 | AR29: =IFERROR(H29-AN29,0) -> 0 | AS29: =IFERROR(I29-AO29,0) -> -0.64702384 | AU29: =Act!L28 -> -23.077292 | AV29: =H29-AU29 -> #VALUE! | AX29: =IF('FC5+7'!S$3=1,'FC5+7'!S28,"") -> -29.170027 | AY29: =IF('FC5+7'!T$3=1,'FC5+7'!T28,"") | AZ29: =IF('FC5+7'!U$3=1,'FC5+7'!U28,"") | BA29: =SUM(AX29:AZ29) -> -29.170027 | BB29: =IFERROR(F29-AX29,0) -> 0 | BC29: =IFERROR(G29-AY29,0) -> 0 | BD29: =IFERROR(H29-AZ29,0) -> 0 | BE29: =IFERROR(I29-BA29,0) -> 0 | BG29: =F29 -> -29.170027 | BH29: -28.299801 | BI29: -29.878045 | BJ29: =SUM(BG29:BI29) -> -87.347873 | BK29: =IFERROR(F29-AC29,0) -> -2.5575875 | BL29: =IFERROR(G29-AD29,0) -> 0 | BM29: =IFERROR(AL29-AE29,0) -> 0 | BN29: =IFERROR(I29-BJ29,0) -> 58.177846 | BP29: =F29 -> -29.170027 | BQ29: =G29 | BR29: =#REF! -> #REF! | BS29: =SUM(BP29:BR29) -> #REF! | BT29: =BP29-AC29 -> -2.5575875 | BU29: =BQ29-AD29 -> #VALUE! | BV29: =BR29-AE29 -> #REF! | BW29: =BS29-AF29 -> #REF! | BY29: =H29-BR29 -> #VALUE! | CA29: ='FC2+10'!AA28 -> -77.884931 | CC29: =CA29-I29 -> -48.714903 | CE29: =IF('FC7+5'!S$3=1,'FC7+5'!S28,"") -> -29.170027 | CF29: =IF('FC7+5'!T$3=1,'FC7+5'!T28,"") | CG29: =IF('FC7+5'!U$3=1,'FC7+5'!U28,"") | CH29: =SUM(CE29:CG29) -> -29.170027 | CI29: =IFERROR(F29-CE29,0) -> 0 | CJ29: =IFERROR(G29-CF29,0) -> 0 | CK29: =IFERROR(H29-CG29,0) -> 0 | CL29: =IFERROR(I29-CH29,0) -> 0 | CM29: =IF('FC7+5'!AC$3=1,'FC7+5'!AC28,"") -> -76.523763 | CN29: =I29-CM29 -> 47.353735
D30: VT | F30: =IF(Act!S$3=1,Act!S29,"") -> -5.2709534 | G30: =IF(Act!T$3=1,Act!T29,"") | H30: =IF(Act!U$3=1,Act!U29,"") | I30: =SUM(F30:H30) -> -5.2709534 | K30: =IF(BP!S$3=1,BP!S29,"") -> -5.1304774 | L30: =IF(BP!T$3=1,BP!T29,"") | M30: =IF(BP!U$3=1,BP!U29,"") | N30: =SUM(K30:M30) -> -5.1304774 | O30: =IFERROR(F30-K30,0) -> -0.14047596 | P30: =IFERROR(G30-L30,0) -> 0 | Q30: =IFERROR(H30-M30,0) -> 0 | R30: =I30-N30 -> -0.14047596 | T30: =IF('FC2+10'!S$3=1,'FC2+10'!S29,"") -> -5.2709534 | U30: =IF('FC2+10'!T$3=1,'FC2+10'!T29,"") | V30: =IF('FC2+10'!U$3=1,'FC2+10'!U29,"") | W30: =SUM(T30:V30) -> -5.2709534 | X30: =IFERROR(F30-T30,0) -> 0 | Y30: =IFERROR(G30-U30,0) -> 0 | Z30: =IFERROR(H30-V30,0) -> 0 | AA30: =I30-W30 -> 0 | AC30: =IF(OL!S$3=1,OL!S29,"") -> -1.244592 | AD30: =IF(OL!T$3=1,OL!T29,"") -> -0.42220004 | AE30: =IF(OL!U$3=1,OL!U29,"") | AF30: =SUM(AC30:AE30) -> -1.666792 | AG30: =IFERROR(F30-AC30,0) -> -4.0263614 | AH30: =IFERROR(G30-AD30,0) -> 0 | AI30: =IFERROR(H30-AE30,0) -> 0 | AJ30: =IFERROR(I30-AF30,0) -> -3.6041614 | AL30: =IF(LY!S$3=1,LY!S29,"") -> -6.6325747 | AM30: =IF(LY!T$3=1,LY!T29,"") | AN30: =IF(LY!U$3=1,LY!U29,"") | AO30: =SUM(AL30:AN30) -> -6.6325747 | AP30: =IFERROR(F30-AL30,0) -> 1.3616213 | AQ30: =IFERROR(G30-AM30,0) -> 0 | AR30: =IFERROR(H30-AN30,0) -> 0 | AS30: =IFERROR(I30-AO30,0) -> 1.3616213 | AU30: =Act!L29 -> -0.159096 | AV30: =H30-AU30 -> #VALUE! | AX30: =IF('FC5+7'!S$3=1,'FC5+7'!S29,"") -> -5.2709534 | AY30: =IF('FC5+7'!T$3=1,'FC5+7'!T29,"") | AZ30: =IF('FC5+7'!U$3=1,'FC5+7'!U29,"") | BA30: =SUM(AX30:AZ30) -> -5.2709534 | BB30: =IFERROR(F30-AX30,0) -> 0 | BC30: =IFERROR(G30-AY30,0) -> 0 | BD30: =IFERROR(H30-AZ30,0) -> 0 | BE30: =IFERROR(I30-BA30,0) -> 0 | BG30: =F30 -> -5.2709534 | BH30: -3.5255096 | BI30: -3.7706107 | BJ30: =SUM(BG30:BI30) -> -12.567074 | BK30: =IFERROR(F30-AC30,0) -> -4.0263614 | BL30: =IFERROR(G30-AD30,0) -> 0 | BM30: =IFERROR(AL30-AE30,0) -> 0 | BN30: =IFERROR(I30-BJ30,0) -> 7.2961203 | BP30: =F30 -> -5.2709534 | BQ30: =G30 | BR30: =#REF! -> #REF! | BS30: =SUM(BP30:BR30) -> #REF! | BT30: =BP30-AC30 -> -4.0263614 | BU30: =BQ30-AD30 -> #VALUE! | BV30: =BR30-AE30 -> #REF! | BW30: =BS30-AF30 -> #REF! | BY30: =H30-BR30 -> #VALUE! | CA30: ='FC2+10'!AA29 -> -0.44583333 | CC30: =CA30-I30 -> 4.8251201 | CE30: =IF('FC7+5'!S$3=1,'FC7+5'!S29,"") -> -5.2709534 | CF30: =IF('FC7+5'!T$3=1,'FC7+5'!T29,"") | CG30: =IF('FC7+5'!U$3=1,'FC7+5'!U29,"") | CH30: =SUM(CE30:CG30) -> -5.2709534 | CI30: =IFERROR(F30-CE30,0) -> 0 | CJ30: =IFERROR(G30-CF30,0) -> 0 | CK30: =IFERROR(H30-CG30,0) -> 0 | CL30: =IFERROR(I30-CH30,0) -> 0 | CM30: =IF('FC7+5'!AC$3=1,'FC7+5'!AC29,"") -> -3.5493798 | CN30: =I30-CM30 -> -1.7215736
D31: R&D *except for function | F31: =IF(Act!S$3=1,Act!S30,"") -> 0 | G31: =IF(Act!T$3=1,Act!T30,"") | H31: =IF(Act!U$3=1,Act!U30,"") | I31: =SUM(F31:H31) -> 0 | K31: =IF(BP!S$3=1,BP!S30,"") -> -0.010794793 | L31: =IF(BP!T$3=1,BP!T30,"") | M31: =IF(BP!U$3=1,BP!U30,"") | N31: =SUM(K31:M31) -> -0.010794793 | O31: =IFERROR(F31-K31,0) -> 0.010794793 | P31: =IFERROR(G31-L31,0) -> 0 | Q31: =IFERROR(H31-M31,0) -> 0 | R31: =I31-N31 -> 0.010794793 | T31: =IF('FC2+10'!S$3=1,'FC2+10'!S30,"") -> 0 | U31: =IF('FC2+10'!T$3=1,'FC2+10'!T30,"") | V31: =IF('FC2+10'!U$3=1,'FC2+10'!U30,"") | W31: =SUM(T31:V31) -> 0 | X31: =IFERROR(F31-T31,0) -> 0 | Y31: =IFERROR(G31-U31,0) -> 0 | Z31: =IFERROR(H31-V31,0) -> 0 | AA31: =I31-W31 -> 0 | AC31: =IF(OL!S$3=1,OL!S30,"") -> 0 | AD31: =IF(OL!T$3=1,OL!T30,"") -> 0 | AE31: =IF(OL!U$3=1,OL!U30,"") | AF31: =SUM(AC31:AE31) -> 0 | AG31: =IFERROR(F31-AC31,0) -> 0 | AH31: =IFERROR(G31-AD31,0) -> 0 | AI31: =IFERROR(H31-AE31,0) -> 0 | AJ31: =IFERROR(I31-AF31,0) -> 0 | AL31: =IF(LY!S$3=1,LY!S30,"") -> 0 | AM31: =IF(LY!T$3=1,LY!T30,"") | AN31: =IF(LY!U$3=1,LY!U30,"") | AO31: =SUM(AL31:AN31) -> 0 | AP31: =IFERROR(F31-AL31,0) -> 0 | AQ31: =IFERROR(G31-AM31,0) -> 0 | AR31: =IFERROR(H31-AN31,0) -> 0 | AS31: =IFERROR(I31-AO31,0) -> 0 | AU31: =Act!L30 -> 0 | AV31: =H31-AU31 -> #VALUE! | AX31: =IF('FC5+7'!S$3=1,'FC5+7'!S30,"") -> 0 | AY31: =IF('FC5+7'!T$3=1,'FC5+7'!T30,"") | AZ31: =IF('FC5+7'!U$3=1,'FC5+7'!U30,"") | BA31: =SUM(AX31:AZ31) -> 0 | BB31: =IFERROR(F31-AX31,0) -> 0 | BC31: =IFERROR(G31-AY31,0) -> 0 | BD31: =IFERROR(H31-AZ31,0) -> 0 | BE31: =IFERROR(I31-BA31,0) -> 0 | BG31: =F31 -> 0 | BH31: 0 | BI31: 0 | BJ31: =SUM(BG31:BI31) -> 0 | BK31: =IFERROR(F31-AC31,0) -> 0 | BL31: =IFERROR(G31-AD31,0) -> 0 | BM31: =IFERROR(AL31-AE31,0) -> 0 | BN31: =IFERROR(I31-BJ31,0) -> 0 | BP31: =F31 -> 0 | BQ31: =G31 | BR31: =#REF! -> #REF! | BS31: =SUM(BP31:BR31) -> #REF! | BT31: =BP31-AC31 -> 0 | BU31: =BQ31-AD31 -> #VALUE! | BV31: =BR31-AE31 -> #REF! | BW31: =BS31-AF31 -> #REF! | BY31: =H31-BR31 -> #VALUE! | CA31: ='FC2+10'!AA30 -> 0 | CC31: =CA31-I31 -> 0 | CE31: =IF('FC7+5'!S$3=1,'FC7+5'!S30,"") -> 0 | CF31: =IF('FC7+5'!T$3=1,'FC7+5'!T30,"") | CG31: =IF('FC7+5'!U$3=1,'FC7+5'!U30,"") | CH31: =SUM(CE31:CG31) -> 0 | CI31: =IFERROR(F31-CE31,0) -> 0 | CJ31: =IFERROR(G31-CF31,0) -> 0 | CK31: =IFERROR(H31-CG31,0) -> 0 | CL31: =IFERROR(I31-CH31,0) -> 0 | CM31: =IF('FC7+5'!AC$3=1,'FC7+5'!AC30,"") -> 0 | CN31: =I31-CM31 -> 0
D32: Warranty | F32: =IF(Act!S$3=1,Act!S31,"") -> -22.075094 | G32: =IF(Act!T$3=1,Act!T31,"") | H32: =IF(Act!U$3=1,Act!U31,"") | I32: =SUM(F32:H32) -> -22.075094 | K32: =IF(BP!S$3=1,BP!S31,"") -> -20.539579 | L32: =IF(BP!T$3=1,BP!T31,"") | M32: =IF(BP!U$3=1,BP!U31,"") | N32: =SUM(K32:M32) -> -20.539579 | O32: =IFERROR(F32-K32,0) -> -1.5355154 | P32: =IFERROR(G32-L32,0) -> 0 | Q32: =IFERROR(H32-M32,0) -> 0 | R32: =I32-N32 -> -1.5355154 | T32: =IF('FC2+10'!S$3=1,'FC2+10'!S31,"") -> -22.075094 | U32: =IF('FC2+10'!T$3=1,'FC2+10'!T31,"") | V32: =IF('FC2+10'!U$3=1,'FC2+10'!U31,"") | W32: =SUM(T32:V32) -> -22.075094 | X32: =IFERROR(F32-T32,0) -> 0 | Y32: =IFERROR(G32-U32,0) -> 0 | Z32: =IFERROR(H32-V32,0) -> 0 | AA32: =I32-W32 -> 0 | AC32: =IF(OL!S$3=1,OL!S31,"") -> -8.6311958 | AD32: =IF(OL!T$3=1,OL!T31,"") -> -5.8328414 | AE32: =IF(OL!U$3=1,OL!U31,"") | AF32: =SUM(AC32:AE32) -> -14.464037 | AG32: =IFERROR(F32-AC32,0) -> -13.443898 | AH32: =IFERROR(G32-AD32,0) -> 0 | AI32: =IFERROR(H32-AE32,0) -> 0 | AJ32: =IFERROR(I32-AF32,0) -> -7.611057 | AL32: =IF(LY!S$3=1,LY!S31,"") -> -7.1486413 | AM32: =IF(LY!T$3=1,LY!T31,"") | AN32: =IF(LY!U$3=1,LY!U31,"") | AO32: =SUM(AL32:AN32) -> -7.1486413 | AP32: =IFERROR(F32-AL32,0) -> -14.926453 | AQ32: =IFERROR(G32-AM32,0) -> 0 | AR32: =IFERROR(H32-AN32,0) -> 0 | AS32: =IFERROR(I32-AO32,0) -> -14.926453 | AU32: =Act!L31 -> -9.4293348 | AV32: =H32-AU32 -> #VALUE! | AX32: =IF('FC5+7'!S$3=1,'FC5+7'!S31,"") -> -22.075094 | AY32: =IF('FC5+7'!T$3=1,'FC5+7'!T31,"") | AZ32: =IF('FC5+7'!U$3=1,'FC5+7'!U31,"") | BA32: =SUM(AX32:AZ32) -> -22.075094 | BB32: =IFERROR(F32-AX32,0) -> 0 | BC32: =IFERROR(G32-AY32,0) -> 0 | BD32: =IFERROR(H32-AZ32,0) -> 0 | BE32: =IFERROR(I32-BA32,0) -> 0 | BG32: =F32 -> -22.075094 | BH32: -6.6139372 | BI32: -7.4965247 | BJ32: =SUM(BG32:BI32) -> -36.185556 | BK32: =IFERROR(F32-AC32,0) -> -13.443898 | BL32: =IFERROR(G32-AD32,0) -> 0 | BM32: =IFERROR(AL32-AE32,0) -> 0 | BN32: =IFERROR(I32-BJ32,0) -> 14.110462 | BP32: =F32 -> -22.075094 | BQ32: =G32 | BR32: =#REF! -> #REF! | BS32: =SUM(BP32:BR32) -> #REF! | BT32: =BP32-AC32 -> -13.443898 | BU32: =BQ32-AD32 -> #VALUE! | BV32: =BR32-AE32 -> #REF! | BW32: =BS32-AF32 -> #REF! | BY32: =H32-BR32 -> #VALUE! | CA32: ='FC2+10'!AA31 -> -25.760772 | CC32: =CA32-I32 -> -3.6856782 | CE32: =IF('FC7+5'!S$3=1,'FC7+5'!S31,"") -> -22.075094 | CF32: =IF('FC7+5'!T$3=1,'FC7+5'!T31,"") | CG32: =IF('FC7+5'!U$3=1,'FC7+5'!U31,"") | CH32: =SUM(CE32:CG32) -> -22.075094 | CI32: =IFERROR(F32-CE32,0) -> 0 | CJ32: =IFERROR(G32-CF32,0) -> 0 | CK32: =IFERROR(H32-CG32,0) -> 0 | CL32: =IFERROR(I32-CH32,0) -> 0 | CM32: =IF('FC7+5'!AC$3=1,'FC7+5'!AC31,"") -> -21.783653 | CN32: =I32-CM32 -> -0.29144123
D33: *RS (Global Function Cost) | F33: =IF(Act!S$3=1,Act!S32,"") -> 0 | G33: =IF(Act!T$3=1,Act!T32,"") | H33: =IF(Act!U$3=1,Act!U32,"") | I33: =SUM(F33:H33) -> 0 | K33: =IF(BP!S$3=1,BP!S32,"") -> 0 | L33: =IF(BP!T$3=1,BP!T32,"") | M33: =IF(BP!U$3=1,BP!U32,"") | N33: =SUM(K33:M33) -> 0 | O33: =IFERROR(F33-K33,0) -> 0 | P33: =IFERROR(G33-L33,0) -> 0 | Q33: =IFERROR(H33-M33,0) -> 0 | R33: =I33-N33 -> 0 | T33: =IF('FC2+10'!S$3=1,'FC2+10'!S32,"") -> 0 | U33: =IF('FC2+10'!T$3=1,'FC2+10'!T32,"") | V33: =IF('FC2+10'!U$3=1,'FC2+10'!U32,"") | W33: =SUM(T33:V33) -> 0 | X33: =IFERROR(F33-T33,0) -> 0 | Y33: =IFERROR(G33-U33,0) -> 0 | Z33: =IFERROR(H33-V33,0) -> 0 | AA33: =I33-W33 -> 0 | AC33: =IF(OL!S$3=1,OL!S32,"") -> 0 | AD33: =IF(OL!T$3=1,OL!T32,"") -> 0 | AE33: =IF(OL!U$3=1,OL!U32,"") | AF33: =SUM(AC33:AE33) -> 0 | AG33: =IFERROR(F33-AC33,0) -> 0 | AH33: =IFERROR(G33-AD33,0) -> 0 | AI33: =IFERROR(H33-AE33,0) -> 0 | AJ33: =IFERROR(I33-AF33,0) -> 0 | AL33: =IF(LY!S$3=1,LY!S32,"") -> 0 | AM33: =IF(LY!T$3=1,LY!T32,"") | AN33: =IF(LY!U$3=1,LY!U32,"") | AO33: =SUM(AL33:AN33) -> 0 | AP33: =IFERROR(F33-AL33,0) -> 0 | AQ33: =IFERROR(G33-AM33,0) -> 0 | AR33: =IFERROR(H33-AN33,0) -> 0 | AS33: =IFERROR(I33-AO33,0) -> 0 | AU33: =Act!L32 -> 0 | AV33: =H33-AU33 -> #VALUE! | AX33: =IF('FC5+7'!S$3=1,'FC5+7'!S32,"") -> 0 | AY33: =IF('FC5+7'!T$3=1,'FC5+7'!T32,"") | AZ33: =IF('FC5+7'!U$3=1,'FC5+7'!U32,"") | BA33: =SUM(AX33:AZ33) -> 0 | BB33: =IFERROR(F33-AX33,0) -> 0 | BC33: =IFERROR(G33-AY33,0) -> 0 | BD33: =IFERROR(H33-AZ33,0) -> 0 | BE33: =IFERROR(I33-BA33,0) -> 0 | BG33: =F33 -> 0 | BH33: 0 | BI33: 0 | BJ33: =SUM(BG33:BI33) -> 0 | BK33: =IFERROR(F33-AC33,0) -> 0 | BL33: =IFERROR(G33-AD33,0) -> 0 | BM33: =IFERROR(AL33-AE33,0) -> 0 | BN33: =IFERROR(I33-BJ33,0) -> 0 | BP33: =F33 -> 0 | BQ33: =G33 | BR33: =#REF! -> #REF! | BS33: =SUM(BP33:BR33) -> #REF! | BT33: =BP33-AC33 -> 0 | BU33: =BQ33-AD33 -> #VALUE! | BV33: =BR33-AE33 -> #REF! | BW33: =BS33-AF33 -> #REF! | BY33: =H33-BR33 -> #VALUE! | CA33: ='FC2+10'!AA32 -> 0 | CC33: =CA33-I33 -> 0 | CE33: =IF('FC5+7'!S$3=1,'FC5+7'!S32,"") -> 0 | CF33: =IF('FC5+7'!BA$3=1,'FC5+7'!BA32,"") | CG33: =IF('FC5+7'!BB$3=1,'FC5+7'!BB32,"") | CH33: =SUM(CE33:CG33) -> 0 | CI33: =IFERROR(F33-CE33,0) -> 0 | CJ33: =IFERROR(G33-CF33,0) -> 0 | CK33: =IFERROR(H33-CG33,0) -> 0 | CL33: =IFERROR(I33-CH33,0) -> 0 | CM33: =IF('FC5+7'!AC$3=1,'FC5+7'!AC32,"")
D34: MFG - out of function scope | F34: =IF(Act!S$3=1,Act!S33,"") -> -10.598456 | G34: =IF(Act!T$3=1,Act!T33,"") | H34: =IF(Act!U$3=1,Act!U33,"") | I34: =SUM(F34:H34) -> -10.598456 | K34: =IF(BP!S$3=1,BP!S33,"") -> -28.939301 | L34: =IF(BP!T$3=1,BP!T33,"") | M34: =IF(BP!U$3=1,BP!U33,"") | N34: =SUM(K34:M34) -> -28.939301 | O34: =IFERROR(F34-K34,0) -> 18.340846 | P34: =IFERROR(G34-L34,0) -> 0 | Q34: =IFERROR(H34-M34,0) -> 0 | R34: =I34-N34 -> 18.340846 | T34: =IF('FC2+10'!S$3=1,'FC2+10'!S33,"") -> -10.598456 | U34: =IF('FC2+10'!T$3=1,'FC2+10'!T33,"") | V34: =IF('FC2+10'!U$3=1,'FC2+10'!U33,"") | W34: =SUM(T34:V34) -> -10.598456 | X34: =IFERROR(F34-T34,0) -> 0 | Y34: =IFERROR(G34-U34,0) -> 0 | Z34: =IFERROR(H34-V34,0) -> 0 | AA34: =I34-W34 -> 0 | AC34: =IF(OL!S$3=1,OL!S33,"") -> -12.553722 | AD34: =IF(OL!T$3=1,OL!T33,"") -> -19.115941 | AE34: =IF(OL!U$3=1,OL!U33,"") | AF34: =SUM(AC34:AE34) -> -31.669662 | AG34: =IFERROR(F34-AC34,0) -> 1.955266 | AH34: =IFERROR(G34-AD34,0) -> 0 | AI34: =IFERROR(H34-AE34,0) -> 0 | AJ34: =IFERROR(I34-AF34,0) -> 21.071207 | AL34: =IF(LY!S$3=1,LY!S33,"") -> -10.486304 | AM34: =IF(LY!T$3=1,LY!T33,"") | AN34: =IF(LY!U$3=1,LY!U33,"") | AO34: =SUM(AL34:AN34) -> -10.486304 | AP34: =IFERROR(F34-AL34,0) -> -0.11215198 | AQ34: =IFERROR(G34-AM34,0) -> 0 | AR34: =IFERROR(H34-AN34,0) -> 0 | AS34: =IFERROR(I34-AO34,0) -> -0.11215198 | AU34: =Act!L33 -> -11.56958 | AV34: =H34-AU34 -> #VALUE! | AX34: =IF('FC5+7'!S$3=1,'FC5+7'!S33,"") -> -10.598456 | AY34: =IF('FC5+7'!T$3=1,'FC5+7'!T33,"") | AZ34: =IF('FC5+7'!U$3=1,'FC5+7'!U33,"") | BA34: =SUM(AX34:AZ34) -> -10.598456 | BB34: =IFERROR(F34-AX34,0) -> 0 | BC34: =IFERROR(G34-AY34,0) -> 0 | BD34: =IFERROR(H34-AZ34,0) -> 0 | BE34: =IFERROR(I34-BA34,0) -> 0 | BG34: =F34 -> -10.598456 | BH34: -10.654559 | BI34: -13.487015 | BJ34: =SUM(BG34:BI34) -> -34.74003 | BK34: =IFERROR(F34-AC34,0) -> 1.955266 | BL34: =IFERROR(G34-AD34,0) -> 0 | BM34: =IFERROR(AL34-AE34,0) -> 0 | BN34: =IFERROR(I34-BJ34,0) -> 24.141575 | BP34: =F34 -> -10.598456 | BQ34: =G34 | BR34: =#REF! -> #REF! | BS34: =SUM(BP34:BR34) -> #REF! | BT34: =BP34-AC34 -> 1.955266 | BU34: =BQ34-AD34 -> #VALUE! | BV34: =BR34-AE34 -> #REF! | BW34: =BS34-AF34 -> #REF! | BY34: =H34-BR34 -> #VALUE! | CA34: ='FC2+10'!AA33 -> -32.945411 | CC34: =CA34-I34 -> -22.346956 | CE34: =IF('FC7+5'!S$3=1,'FC7+5'!S33,"") -> -10.598456 | CF34: =IF('FC7+5'!T$3=1,'FC7+5'!T33,"") | CG34: =IF('FC7+5'!U$3=1,'FC7+5'!U33,"") | CH34: =SUM(CE34:CG34) -> -10.598456 | CI34: =IFERROR(F34-CE34,0) -> 0 | CJ34: =IFERROR(G34-CF34,0) -> 0 | CK34: =IFERROR(H34-CG34,0) -> 0 | CL34: =IFERROR(I34-CH34,0) -> 0 | CM34: =IF('FC7+5'!AC$3=1,'FC7+5'!AC33,"") -> -39.479261 | CN34: =I34-CM34 -> 28.880805
